2024-10-15 22:41:15,557 INFO Blueprints registered successfully: /home/frank/eazy_manage_backend/./app.py 76
2024-10-15 22:41:15,558 INFO Mail service setup successfully: /home/frank/eazy_manage_backend/./app.py 89
2024-10-15 22:41:15,558 INFO App created successfully: /home/frank/eazy_manage_backend/./app.py 99
2024-10-15 22:41:16,097 INFO Logging setup successfully: /home/frank/eazy_manage_backend/app.py 43
2024-10-15 22:41:16,097 INFO DataBase set up successfully: /home/frank/eazy_manage_backend/app.py 55
2024-10-15 22:41:16,251 INFO database set up successfully: /home/frank/eazy_manage_backend/app.py 60
2024-10-15 22:41:16,256 INFO Migrations set up successfully: /home/frank/eazy_manage_backend/app.py 68
2024-10-15 22:41:16,263 INFO Blueprints registered successfully: /home/frank/eazy_manage_backend/app.py 76
2024-10-15 22:41:16,264 INFO Mail service setup successfully: /home/frank/eazy_manage_backend/app.py 89
2024-10-15 22:41:16,264 INFO App created successfully: /home/frank/eazy_manage_backend/app.py 99
2024-10-15 22:48:03,405 INFO Logging setup successfully: /home/frank/eazy_manage_backend/./app.py 43
2024-10-15 22:48:03,405 INFO DataBase set up successfully: /home/frank/eazy_manage_backend/./app.py 55
2024-10-15 22:48:03,607 INFO database set up successfully: /home/frank/eazy_manage_backend/./app.py 60
2024-10-15 22:48:03,611 INFO Migrations set up successfully: /home/frank/eazy_manage_backend/./app.py 68
2024-10-15 22:48:03,623 INFO Blueprints registered successfully: /home/frank/eazy_manage_backend/./app.py 76
2024-10-15 22:48:03,623 INFO Mail service setup successfully: /home/frank/eazy_manage_backend/./app.py 89
2024-10-15 22:48:03,624 INFO App created successfully: /home/frank/eazy_manage_backend/./app.py 99
2024-10-15 22:48:28,000 INFO Logging setup successfully: /home/frank/eazy_manage_backend/./app.py 43
2024-10-15 22:48:28,001 INFO DataBase set up successfully: /home/frank/eazy_manage_backend/./app.py 55
2024-10-15 22:48:28,124 INFO database set up successfully: /home/frank/eazy_manage_backend/./app.py 60
2024-10-15 22:48:28,133 INFO Migrations set up successfully: /home/frank/eazy_manage_backend/./app.py 68
2024-10-15 22:48:28,146 INFO Blueprints registered successfully: /home/frank/eazy_manage_backend/./app.py 76
2024-10-15 22:48:28,147 INFO Mail service setup successfully: /home/frank/eazy_manage_backend/./app.py 89
2024-10-15 22:48:28,147 INFO App created successfully: /home/frank/eazy_manage_backend/./app.py 99
2024-10-15 22:48:46,171 INFO Logging setup successfully: /home/frank/eazy_manage_backend/./app.py 43
2024-10-15 22:48:46,172 INFO DataBase set up successfully: /home/frank/eazy_manage_backend/./app.py 55
2024-10-15 22:48:46,379 INFO database set up successfully: /home/frank/eazy_manage_backend/./app.py 60
2024-10-15 22:48:46,386 INFO Migrations set up successfully: /home/frank/eazy_manage_backend/./app.py 68
2024-10-15 22:48:46,396 INFO Blueprints registered successfully: /home/frank/eazy_manage_backend/./app.py 76
2024-10-15 22:48:46,397 INFO Mail service setup successfully: /home/frank/eazy_manage_backend/./app.py 89
2024-10-15 22:48:46,397 INFO App created successfully: /home/frank/eazy_manage_backend/./app.py 99
2024-10-15 22:49:12,054 INFO Logging setup successfully: /home/frank/eazy_manage_backend/./app.py 43
2024-10-15 22:49:12,054 INFO DataBase set up successfully: /home/frank/eazy_manage_backend/./app.py 55
2024-10-15 22:49:12,100 INFO database set up successfully: /home/frank/eazy_manage_backend/./app.py 60
2024-10-15 22:49:12,103 INFO Migrations set up successfully: /home/frank/eazy_manage_backend/./app.py 68
2024-10-15 22:49:12,109 INFO Blueprints registered successfully: /home/frank/eazy_manage_backend/./app.py 76
2024-10-15 22:49:12,109 INFO Mail service setup successfully: /home/frank/eazy_manage_backend/./app.py 89
2024-10-15 22:49:12,110 INFO App created successfully: /home/frank/eazy_manage_backend/./app.py 99
2024-10-15 22:49:31,858 INFO Logging setup successfully: /home/frank/eazy_manage_backend/./app.py 43
2024-10-15 22:49:31,858 INFO DataBase set up successfully: /home/frank/eazy_manage_backend/./app.py 55
2024-10-15 22:49:32,033 INFO database set up successfully: /home/frank/eazy_manage_backend/./app.py 60
2024-10-15 22:49:32,036 INFO Migrations set up successfully: /home/frank/eazy_manage_backend/./app.py 68
2024-10-15 22:49:32,042 INFO Blueprints registered successfully: /home/frank/eazy_manage_backend/./app.py 76
2024-10-15 22:49:32,043 INFO Mail service setup successfully: /home/frank/eazy_manage_backend/./app.py 89
2024-10-15 22:49:32,043 INFO App created successfully: /home/frank/eazy_manage_backend/./app.py 99
2024-10-15 22:56:22,687 INFO Logging setup successfully: /home/frank/eazy_manage_backend/./app.py 43
2024-10-15 22:56:22,688 INFO DataBase set up successfully: /home/frank/eazy_manage_backend/./app.py 55
2024-10-15 22:56:22,893 INFO database set up successfully: /home/frank/eazy_manage_backend/./app.py 60
2024-10-15 22:56:22,895 INFO Migrations set up successfully: /home/frank/eazy_manage_backend/./app.py 68
2024-10-15 22:56:22,899 INFO Blueprints registered successfully: /home/frank/eazy_manage_backend/./app.py 76
2024-10-15 22:56:22,899 INFO Mail service setup successfully: /home/frank/eazy_manage_backend/./app.py 89
2024-10-15 22:56:22,899 INFO App created successfully: /home/frank/eazy_manage_backend/./app.py 99
2024-10-15 23:38:44,713 ERROR Validation error on login: {'error': {'type': 'ValidationError', 'message': {'pwd': ['Unknown field.']}}}: /home/frank/eazy_manage_backend/api/v1/routes/auth.py 100
2024-10-15 23:38:53,585 ERROR Validation error on login: {'error': {'type': 'ValidationError', 'message': {'pwd': ['Unknown field.']}}}: /home/frank/eazy_manage_backend/api/v1/routes/auth.py 100
2024-10-15 23:38:53,700 ERROR Validation error on login: {'error': {'type': 'ValidationError', 'message': {'pwd': ['Unknown field.']}}}: /home/frank/eazy_manage_backend/api/v1/routes/auth.py 100
2024-10-15 23:38:53,876 ERROR Validation error on login: {'error': {'type': 'ValidationError', 'message': {'pwd': ['Unknown field.']}}}: /home/frank/eazy_manage_backend/api/v1/routes/auth.py 100
2024-10-15 23:38:56,221 ERROR Validation error on login: {'error': {'type': 'ValidationError', 'message': {'pwd': ['Unknown field.']}}}: /home/frank/eazy_manage_backend/api/v1/routes/auth.py 100
2024-10-15 23:38:56,375 ERROR Validation error on login: {'error': {'type': 'ValidationError', 'message': {'pwd': ['Unknown field.']}}}: /home/frank/eazy_manage_backend/api/v1/routes/auth.py 100
2024-10-15 23:38:56,544 ERROR Validation error on login: {'error': {'type': 'ValidationError', 'message': {'pwd': ['Unknown field.']}}}: /home/frank/eazy_manage_backend/api/v1/routes/auth.py 100
2024-10-15 23:38:56,742 ERROR Validation error on login: {'error': {'type': 'ValidationError', 'message': {'pwd': ['Unknown field.']}}}: /home/frank/eazy_manage_backend/api/v1/routes/auth.py 100
2024-10-15 23:38:56,892 ERROR Validation error on login: {'error': {'type': 'ValidationError', 'message': {'pwd': ['Unknown field.']}}}: /home/frank/eazy_manage_backend/api/v1/routes/auth.py 100
2024-10-15 23:38:57,055 ERROR Validation error on login: {'error': {'type': 'ValidationError', 'message': {'pwd': ['Unknown field.']}}}: /home/frank/eazy_manage_backend/api/v1/routes/auth.py 100
2024-10-15 23:38:57,241 ERROR Validation error on login: {'error': {'type': 'ValidationError', 'message': {'pwd': ['Unknown field.']}}}: /home/frank/eazy_manage_backend/api/v1/routes/auth.py 100
2024-10-15 23:38:57,430 ERROR Validation error on login: {'error': {'type': 'ValidationError', 'message': {'pwd': ['Unknown field.']}}}: /home/frank/eazy_manage_backend/api/v1/routes/auth.py 100
2024-10-15 23:38:57,564 ERROR Validation error on login: {'error': {'type': 'ValidationError', 'message': {'pwd': ['Unknown field.']}}}: /home/frank/eazy_manage_backend/api/v1/routes/auth.py 100
2024-10-15 23:38:57,646 ERROR Validation error on login: {'error': {'type': 'ValidationError', 'message': {'pwd': ['Unknown field.']}}}: /home/frank/eazy_manage_backend/api/v1/routes/auth.py 100
2024-10-15 23:38:57,810 ERROR Validation error on login: {'error': {'type': 'ValidationError', 'message': {'pwd': ['Unknown field.']}}}: /home/frank/eazy_manage_backend/api/v1/routes/auth.py 100
2024-10-15 23:38:57,889 ERROR Validation error on login: {'error': {'type': 'ValidationError', 'message': {'pwd': ['Unknown field.']}}}: /home/frank/eazy_manage_backend/api/v1/routes/auth.py 100
2024-10-15 23:38:58,007 ERROR Validation error on login: {'error': {'type': 'ValidationError', 'message': {'pwd': ['Unknown field.']}}}: /home/frank/eazy_manage_backend/api/v1/routes/auth.py 100
2024-10-15 23:38:58,233 ERROR Validation error on login: {'error': {'type': 'ValidationError', 'message': {'pwd': ['Unknown field.']}}}: /home/frank/eazy_manage_backend/api/v1/routes/auth.py 100
2024-10-15 23:38:58,350 ERROR Validation error on login: {'error': {'type': 'ValidationError', 'message': {'pwd': ['Unknown field.']}}}: /home/frank/eazy_manage_backend/api/v1/routes/auth.py 100
2024-10-15 23:38:58,499 ERROR Validation error on login: {'error': {'type': 'ValidationError', 'message': {'pwd': ['Unknown field.']}}}: /home/frank/eazy_manage_backend/api/v1/routes/auth.py 100
2024-10-15 23:38:58,686 ERROR Validation error on login: {'error': {'type': 'ValidationError', 'message': {'pwd': ['Unknown field.']}}}: /home/frank/eazy_manage_backend/api/v1/routes/auth.py 100
2024-10-15 23:48:45,176 ERROR An error occured while logging in: /home/frank/eazy_manage_backend/api/v1/routes/auth.py 125
Traceback (most recent call last):
  File "/home/frank/eazy_manage_backend/api/v1/routes/auth.py", line 110, in login
    user = db.session.query(Users).filter_by(email=email).first()
  File "/home/frank/.local/lib/python3.10/site-packages/sqlalchemy/orm/scoping.py", line 1683, in query
    return self._proxied.query(*entities, **kwargs)
  File "/home/frank/.local/lib/python3.10/site-packages/sqlalchemy/orm/session.py", line 2896, in query
    return self._query_cls(entities, self, **kwargs)
  File "/home/frank/.local/lib/python3.10/site-packages/sqlalchemy/orm/query.py", line 275, in __init__
    self._set_entities(entities)
  File "/home/frank/.local/lib/python3.10/site-packages/sqlalchemy/orm/query.py", line 287, in _set_entities
    self._raw_columns = [
  File "/home/frank/.local/lib/python3.10/site-packages/sqlalchemy/orm/query.py", line 288, in <listcomp>
    coercions.expect(
  File "/home/frank/.local/lib/python3.10/site-packages/sqlalchemy/sql/coercions.py", line 389, in expect
    insp._post_inspect
  File "/home/frank/.local/lib/python3.10/site-packages/sqlalchemy/util/langhelpers.py", line 1252, in __get__
    obj.__dict__[self.__name__] = result = self.fget(obj)
  File "/home/frank/.local/lib/python3.10/site-packages/sqlalchemy/orm/mapper.py", line 2711, in _post_inspect
    self._check_configure()
  File "/home/frank/.local/lib/python3.10/site-packages/sqlalchemy/orm/mapper.py", line 2388, in _check_configure
    _configure_registries({self.registry}, cascade=True)
  File "/home/frank/.local/lib/python3.10/site-packages/sqlalchemy/orm/mapper.py", line 4203, in _configure_registries
    _do_configure_registries(registries, cascade)
  File "/home/frank/.local/lib/python3.10/site-packages/sqlalchemy/orm/mapper.py", line 4244, in _do_configure_registries
    mapper._post_configure_properties()
  File "/home/frank/.local/lib/python3.10/site-packages/sqlalchemy/orm/mapper.py", line 2405, in _post_configure_properties
    prop.init()
  File "/home/frank/.local/lib/python3.10/site-packages/sqlalchemy/orm/interfaces.py", line 579, in init
    self.do_init()
  File "/home/frank/.local/lib/python3.10/site-packages/sqlalchemy/orm/relationships.py", line 1647, in do_init
    self._generate_backref()
  File "/home/frank/.local/lib/python3.10/site-packages/sqlalchemy/orm/relationships.py", line 2135, in _generate_backref
    self._add_reverse_property(self.back_populates)
  File "/home/frank/.local/lib/python3.10/site-packages/sqlalchemy/orm/relationships.py", line 1580, in _add_reverse_property
    raise sa_exc.InvalidRequestError(
sqlalchemy.exc.InvalidRequestError: back_populates on relationship 'Users.task' refers to attribute 'Tasks.user_id' that is not a relationship.  The back_populates parameter should refer to the name of a relationship on the target class.
2024-10-15 23:54:40,061 INFO Logging setup successfully: /home/frank/eazy_manage_backend/./app.py 43
2024-10-15 23:54:40,079 INFO DataBase set up successfully: /home/frank/eazy_manage_backend/./app.py 55
2024-10-15 23:54:41,789 INFO database set up successfully: /home/frank/eazy_manage_backend/./app.py 60
2024-10-15 23:54:41,804 INFO Migrations set up successfully: /home/frank/eazy_manage_backend/./app.py 68
2024-10-15 23:54:41,831 INFO Blueprints registered successfully: /home/frank/eazy_manage_backend/./app.py 76
2024-10-15 23:54:41,832 INFO Mail service setup successfully: /home/frank/eazy_manage_backend/./app.py 89
2024-10-15 23:54:41,833 INFO App created successfully: /home/frank/eazy_manage_backend/./app.py 99
2024-10-15 23:54:49,236 ERROR An error occured while logging in: /home/frank/eazy_manage_backend/api/v1/routes/auth.py 125
Traceback (most recent call last):
  File "/home/frank/eazy_manage_backend/api/v1/routes/auth.py", line 117, in login
    hashed_pwd = user['password']
TypeError: 'Users' object is not subscriptable
2024-10-15 23:55:54,751 INFO Logging setup successfully: /home/frank/eazy_manage_backend/./app.py 43
2024-10-15 23:55:54,760 INFO DataBase set up successfully: /home/frank/eazy_manage_backend/./app.py 55
2024-10-15 23:55:55,138 INFO database set up successfully: /home/frank/eazy_manage_backend/./app.py 60
2024-10-15 23:55:55,140 INFO Migrations set up successfully: /home/frank/eazy_manage_backend/./app.py 68
2024-10-15 23:55:55,144 INFO Blueprints registered successfully: /home/frank/eazy_manage_backend/./app.py 76
2024-10-15 23:55:55,144 INFO Mail service setup successfully: /home/frank/eazy_manage_backend/./app.py 89
2024-10-15 23:55:55,144 INFO App created successfully: /home/frank/eazy_manage_backend/./app.py 99
2024-10-15 23:56:02,830 ERROR An error occured while logging in: /home/frank/eazy_manage_backend/api/v1/routes/auth.py 125
Traceback (most recent call last):
  File "/home/frank/eazy_manage_backend/api/v1/routes/auth.py", line 118, in login
    role = user['role']
TypeError: 'Users' object is not subscriptable
2024-10-15 23:57:59,851 INFO Logging setup successfully: /home/frank/eazy_manage_backend/./app.py 43
2024-10-15 23:57:59,859 INFO DataBase set up successfully: /home/frank/eazy_manage_backend/./app.py 55
2024-10-15 23:58:00,518 INFO database set up successfully: /home/frank/eazy_manage_backend/./app.py 60
2024-10-15 23:58:00,521 INFO Migrations set up successfully: /home/frank/eazy_manage_backend/./app.py 68
2024-10-15 23:58:00,526 INFO Blueprints registered successfully: /home/frank/eazy_manage_backend/./app.py 76
2024-10-15 23:58:00,526 INFO Mail service setup successfully: /home/frank/eazy_manage_backend/./app.py 89
2024-10-15 23:58:00,526 INFO App created successfully: /home/frank/eazy_manage_backend/./app.py 99
