2024-08-09 00:23:28,775 INFO Blueprints registered successfully: /home/frank/virtual_doctor_backend/./app.py 82
2024-08-09 00:23:28,776 INFO Mail service setup successfully: /home/frank/virtual_doctor_backend/./app.py 95
2024-08-09 00:23:28,776 INFO App created successfully: /home/frank/virtual_doctor_backend/./app.py 105
2024-08-09 00:56:20,430 INFO Logging setup successfully: /home/frank/virtual_doctor_backend/./app.py 32
2024-08-09 00:56:20,431 INFO Uploads directory set up successfully: /home/frank/virtual_doctor_backend/./app.py 50
NoneType: None
2024-08-09 00:56:20,432 INFO DataBase set up successfully: /home/frank/virtual_doctor_backend/./app.py 62
2024-08-09 00:56:20,705 INFO Migrations set up successfully: /home/frank/virtual_doctor_backend/./app.py 74
2024-08-09 00:56:20,751 INFO Blueprints registered successfully: /home/frank/virtual_doctor_backend/./app.py 82
2024-08-09 00:56:20,752 INFO Mail service setup successfully: /home/frank/virtual_doctor_backend/./app.py 95
2024-08-09 00:56:20,752 INFO App created successfully: /home/frank/virtual_doctor_backend/./app.py 105
2024-08-09 00:57:19,519 INFO Logging setup successfully: /home/frank/virtual_doctor_backend/./app.py 32
2024-08-09 00:57:19,519 INFO Uploads directory set up successfully: /home/frank/virtual_doctor_backend/./app.py 50
NoneType: None
2024-08-09 00:57:19,520 INFO DataBase set up successfully: /home/frank/virtual_doctor_backend/./app.py 62
2024-08-09 00:57:19,633 INFO Migrations set up successfully: /home/frank/virtual_doctor_backend/./app.py 74
2024-08-09 00:57:19,691 INFO Blueprints registered successfully: /home/frank/virtual_doctor_backend/./app.py 82
2024-08-09 00:57:19,691 INFO Mail service setup successfully: /home/frank/virtual_doctor_backend/./app.py 95
2024-08-09 00:57:19,692 INFO App created successfully: /home/frank/virtual_doctor_backend/./app.py 105
2024-08-09 01:06:40,090 INFO Logging setup successfully: /home/frank/virtual_doctor_backend/app.py 32
2024-08-09 01:06:40,091 INFO Uploads directory set up successfully: /home/frank/virtual_doctor_backend/app.py 50
NoneType: None
2024-08-09 01:06:40,092 INFO DataBase set up successfully: /home/frank/virtual_doctor_backend/app.py 62
2024-08-09 01:06:40,231 INFO Migrations set up successfully: /home/frank/virtual_doctor_backend/app.py 74
2024-08-09 01:06:40,296 INFO Blueprints registered successfully: /home/frank/virtual_doctor_backend/app.py 82
2024-08-09 01:06:40,297 INFO Mail service setup successfully: /home/frank/virtual_doctor_backend/app.py 95
2024-08-09 01:06:40,298 INFO App created successfully: /home/frank/virtual_doctor_backend/app.py 105
2024-08-09 01:16:13,833 INFO Logging setup successfully: /home/frank/virtual_doctor_backend/./app.py 32
2024-08-09 01:16:13,833 INFO Uploads directory set up successfully: /home/frank/virtual_doctor_backend/./app.py 50
NoneType: None
2024-08-09 01:16:13,834 INFO DataBase set up successfully: /home/frank/virtual_doctor_backend/./app.py 62
2024-08-09 01:16:13,967 INFO Migrations set up successfully: /home/frank/virtual_doctor_backend/./app.py 74
2024-08-09 01:16:14,040 INFO Blueprints registered successfully: /home/frank/virtual_doctor_backend/./app.py 82
2024-08-09 01:16:14,041 INFO Mail service setup successfully: /home/frank/virtual_doctor_backend/./app.py 95
2024-08-09 01:16:14,042 INFO App created successfully: /home/frank/virtual_doctor_backend/./app.py 105
2024-08-09 01:18:42,104 INFO Logging setup successfully: /home/frank/virtual_doctor_backend/./app.py 32
2024-08-09 01:18:42,104 INFO Uploads directory set up successfully: /home/frank/virtual_doctor_backend/./app.py 50
NoneType: None
2024-08-09 01:18:42,105 INFO DataBase set up successfully: /home/frank/virtual_doctor_backend/./app.py 62
2024-08-09 01:18:42,213 INFO Migrations set up successfully: /home/frank/virtual_doctor_backend/./app.py 74
2024-08-09 01:18:42,241 INFO Blueprints registered successfully: /home/frank/virtual_doctor_backend/./app.py 82
2024-08-09 01:18:42,242 INFO Mail service setup successfully: /home/frank/virtual_doctor_backend/./app.py 95
2024-08-09 01:18:42,242 INFO App created successfully: /home/frank/virtual_doctor_backend/./app.py 105
2024-08-09 01:19:28,880 INFO Logging setup successfully: /home/frank/virtual_doctor_backend/./app.py 32
2024-08-09 01:19:28,881 INFO Uploads directory set up successfully: /home/frank/virtual_doctor_backend/./app.py 50
NoneType: None
2024-08-09 01:19:28,882 INFO DataBase set up successfully: /home/frank/virtual_doctor_backend/./app.py 62
2024-08-09 01:19:29,189 INFO Migrations set up successfully: /home/frank/virtual_doctor_backend/./app.py 74
2024-08-09 01:19:29,269 INFO Blueprints registered successfully: /home/frank/virtual_doctor_backend/./app.py 82
2024-08-09 01:19:29,270 INFO Mail service setup successfully: /home/frank/virtual_doctor_backend/./app.py 95
2024-08-09 01:19:29,270 INFO App created successfully: /home/frank/virtual_doctor_backend/./app.py 105
2024-08-09 01:19:37,614 ERROR An error occured while setting the password: /home/frank/virtual_doctor_backend/models/base_model.py 12
Traceback (most recent call last):
  File "/home/frank/virtual_doctor_backend/models/base_model.py", line 9, in set_pwd
    self.password = bcrypt.hashpw(password.encode('UTF-8'), bcrypt.gensalt())
AttributeError: 'int' object has no attribute 'encode'
2024-08-09 01:19:37,758 ERROR hospital registration failed: /home/frank/virtual_doctor_backend/api/auth.py 93
Traceback (most recent call last):
  File "/home/frank/.local/lib/python3.10/site-packages/sqlalchemy/engine/base.py", line 1970, in _exec_single_context
    self.dialect.do_execute(
  File "/home/frank/.local/lib/python3.10/site-packages/sqlalchemy/engine/default.py", line 924, in do_execute
    cursor.execute(statement, parameters)
  File "/home/frank/.local/lib/python3.10/site-packages/pymysql/cursors.py", line 153, in execute
    result = self._query(query)
  File "/home/frank/.local/lib/python3.10/site-packages/pymysql/cursors.py", line 322, in _query
    conn.query(q)
  File "/home/frank/.local/lib/python3.10/site-packages/pymysql/connections.py", line 563, in query
    self._affected_rows = self._read_query_result(unbuffered=unbuffered)
  File "/home/frank/.local/lib/python3.10/site-packages/pymysql/connections.py", line 825, in _read_query_result
    result.read()
  File "/home/frank/.local/lib/python3.10/site-packages/pymysql/connections.py", line 1199, in read
    first_packet = self.connection._read_packet()
  File "/home/frank/.local/lib/python3.10/site-packages/pymysql/connections.py", line 775, in _read_packet
    packet.raise_for_error()
  File "/home/frank/.local/lib/python3.10/site-packages/pymysql/protocol.py", line 219, in raise_for_error
    err.raise_mysql_exception(self._data)
  File "/home/frank/.local/lib/python3.10/site-packages/pymysql/err.py", line 150, in raise_mysql_exception
    raise errorclass(errno, errval)
pymysql.err.DataError: (1265, "Data truncated for column 'verification' at row 1")

The above exception was the direct cause of the following exception:

Traceback (most recent call last):
  File "/home/frank/virtual_doctor_backend/api/auth.py", line 90, in register
    db.session.commit()
  File "/home/frank/.local/lib/python3.10/site-packages/sqlalchemy/orm/scoping.py", line 597, in commit
    return self._proxied.commit()
  File "/home/frank/.local/lib/python3.10/site-packages/sqlalchemy/orm/session.py", line 1972, in commit
    trans.commit(_to_root=True)
  File "<string>", line 2, in commit
  File "/home/frank/.local/lib/python3.10/site-packages/sqlalchemy/orm/state_changes.py", line 139, in _go
    ret_value = fn(self, *arg, **kw)
  File "/home/frank/.local/lib/python3.10/site-packages/sqlalchemy/orm/session.py", line 1257, in commit
    self._prepare_impl()
  File "<string>", line 2, in _prepare_impl
  File "/home/frank/.local/lib/python3.10/site-packages/sqlalchemy/orm/state_changes.py", line 139, in _go
    ret_value = fn(self, *arg, **kw)
  File "/home/frank/.local/lib/python3.10/site-packages/sqlalchemy/orm/session.py", line 1232, in _prepare_impl
    self.session.flush()
  File "/home/frank/.local/lib/python3.10/site-packages/sqlalchemy/orm/session.py", line 4296, in flush
    self._flush(objects)
  File "/home/frank/.local/lib/python3.10/site-packages/sqlalchemy/orm/session.py", line 4431, in _flush
    with util.safe_reraise():
  File "/home/frank/.local/lib/python3.10/site-packages/sqlalchemy/util/langhelpers.py", line 146, in __exit__
    raise exc_value.with_traceback(exc_tb)
  File "/home/frank/.local/lib/python3.10/site-packages/sqlalchemy/orm/session.py", line 4392, in _flush
    flush_context.execute()
  File "/home/frank/.local/lib/python3.10/site-packages/sqlalchemy/orm/unitofwork.py", line 466, in execute
    rec.execute(self)
  File "/home/frank/.local/lib/python3.10/site-packages/sqlalchemy/orm/unitofwork.py", line 642, in execute
    util.preloaded.orm_persistence.save_obj(
  File "/home/frank/.local/lib/python3.10/site-packages/sqlalchemy/orm/persistence.py", line 93, in save_obj
    _emit_insert_statements(
  File "/home/frank/.local/lib/python3.10/site-packages/sqlalchemy/orm/persistence.py", line 1233, in _emit_insert_statements
    result = connection.execute(
  File "/home/frank/.local/lib/python3.10/site-packages/sqlalchemy/engine/base.py", line 1421, in execute
    return meth(
  File "/home/frank/.local/lib/python3.10/site-packages/sqlalchemy/sql/elements.py", line 514, in _execute_on_connection
    return connection._execute_clauseelement(
  File "/home/frank/.local/lib/python3.10/site-packages/sqlalchemy/engine/base.py", line 1643, in _execute_clauseelement
    ret = self._execute_context(
  File "/home/frank/.local/lib/python3.10/site-packages/sqlalchemy/engine/base.py", line 1849, in _execute_context
    return self._exec_single_context(
  File "/home/frank/.local/lib/python3.10/site-packages/sqlalchemy/engine/base.py", line 1989, in _exec_single_context
    self._handle_dbapi_exception(
  File "/home/frank/.local/lib/python3.10/site-packages/sqlalchemy/engine/base.py", line 2356, in _handle_dbapi_exception
    raise sqlalchemy_exception.with_traceback(exc_info[2]) from e
  File "/home/frank/.local/lib/python3.10/site-packages/sqlalchemy/engine/base.py", line 1970, in _exec_single_context
    self.dialect.do_execute(
  File "/home/frank/.local/lib/python3.10/site-packages/sqlalchemy/engine/default.py", line 924, in do_execute
    cursor.execute(statement, parameters)
  File "/home/frank/.local/lib/python3.10/site-packages/pymysql/cursors.py", line 153, in execute
    result = self._query(query)
  File "/home/frank/.local/lib/python3.10/site-packages/pymysql/cursors.py", line 322, in _query
    conn.query(q)
  File "/home/frank/.local/lib/python3.10/site-packages/pymysql/connections.py", line 563, in query
    self._affected_rows = self._read_query_result(unbuffered=unbuffered)
  File "/home/frank/.local/lib/python3.10/site-packages/pymysql/connections.py", line 825, in _read_query_result
    result.read()
  File "/home/frank/.local/lib/python3.10/site-packages/pymysql/connections.py", line 1199, in read
    first_packet = self.connection._read_packet()
  File "/home/frank/.local/lib/python3.10/site-packages/pymysql/connections.py", line 775, in _read_packet
    packet.raise_for_error()
  File "/home/frank/.local/lib/python3.10/site-packages/pymysql/protocol.py", line 219, in raise_for_error
    err.raise_mysql_exception(self._data)
  File "/home/frank/.local/lib/python3.10/site-packages/pymysql/err.py", line 150, in raise_mysql_exception
    raise errorclass(errno, errval)
sqlalchemy.exc.DataError: (pymysql.err.DataError) (1265, "Data truncated for column 'verification' at row 1")
[SQL: INSERT INTO hospitals (hosp_uuid, hosp_name, hosp_address, contact, email, password, verification, reg_date) VALUES (%(hosp_uuid)s, %(hosp_name)s, %(hosp_address)s, %(contact)s, %(email)s, %(password)s, %(verification)s, %(reg_date)s)]
[parameters: {'hosp_uuid': 'd6e3a1fb-90c1-4821-befb-2e0974335aee', 'hosp_name': 'virtual doctor', 'hosp_address': 'Ngong, Kajiado, Kenya', 'contact': '0783033211', 'email': 'frankchege698@gmail.com', 'password': None, 'verification': 'unverified', 'reg_date': None}]
(Background on this error at: https://sqlalche.me/e/20/9h9h)
2024-08-09 01:24:04,994 INFO Logging setup successfully: /home/frank/virtual_doctor_backend/./app.py 32
2024-08-09 01:24:04,995 INFO Uploads directory set up successfully: /home/frank/virtual_doctor_backend/./app.py 50
NoneType: None
2024-08-09 01:24:04,995 INFO DataBase set up successfully: /home/frank/virtual_doctor_backend/./app.py 62
2024-08-09 01:24:05,161 INFO Migrations set up successfully: /home/frank/virtual_doctor_backend/./app.py 74
2024-08-09 01:24:05,211 INFO Blueprints registered successfully: /home/frank/virtual_doctor_backend/./app.py 82
2024-08-09 01:24:05,211 INFO Mail service setup successfully: /home/frank/virtual_doctor_backend/./app.py 95
2024-08-09 01:24:05,212 INFO App created successfully: /home/frank/virtual_doctor_backend/./app.py 105
2024-08-09 01:24:17,005 INFO Logging setup successfully: /home/frank/virtual_doctor_backend/./app.py 32
2024-08-09 01:24:17,006 INFO Uploads directory set up successfully: /home/frank/virtual_doctor_backend/./app.py 50
NoneType: None
2024-08-09 01:24:17,006 INFO DataBase set up successfully: /home/frank/virtual_doctor_backend/./app.py 62
2024-08-09 01:24:17,161 INFO Migrations set up successfully: /home/frank/virtual_doctor_backend/./app.py 74
2024-08-09 01:24:17,197 INFO Blueprints registered successfully: /home/frank/virtual_doctor_backend/./app.py 82
2024-08-09 01:24:17,197 INFO Mail service setup successfully: /home/frank/virtual_doctor_backend/./app.py 95
2024-08-09 01:24:17,198 INFO App created successfully: /home/frank/virtual_doctor_backend/./app.py 105
2024-08-09 01:24:48,717 INFO Logging setup successfully: /home/frank/virtual_doctor_backend/app.py 32
2024-08-09 01:24:48,718 INFO Uploads directory set up successfully: /home/frank/virtual_doctor_backend/app.py 50
NoneType: None
2024-08-09 01:24:48,718 INFO DataBase set up successfully: /home/frank/virtual_doctor_backend/app.py 62
2024-08-09 01:24:48,873 INFO Migrations set up successfully: /home/frank/virtual_doctor_backend/app.py 74
2024-08-09 01:24:48,974 INFO Blueprints registered successfully: /home/frank/virtual_doctor_backend/app.py 82
2024-08-09 01:24:48,975 INFO Mail service setup successfully: /home/frank/virtual_doctor_backend/app.py 95
2024-08-09 01:24:48,976 INFO App created successfully: /home/frank/virtual_doctor_backend/app.py 105
2024-08-09 01:25:09,745 INFO Logging setup successfully: /home/frank/virtual_doctor_backend/app.py 32
2024-08-09 01:25:09,746 INFO Uploads directory set up successfully: /home/frank/virtual_doctor_backend/app.py 50
NoneType: None
2024-08-09 01:25:09,747 INFO DataBase set up successfully: /home/frank/virtual_doctor_backend/app.py 62
2024-08-09 01:25:09,925 INFO Migrations set up successfully: /home/frank/virtual_doctor_backend/app.py 74
2024-08-09 01:25:10,053 INFO Blueprints registered successfully: /home/frank/virtual_doctor_backend/app.py 82
2024-08-09 01:25:10,054 INFO Mail service setup successfully: /home/frank/virtual_doctor_backend/app.py 95
2024-08-09 01:25:10,054 INFO App created successfully: /home/frank/virtual_doctor_backend/app.py 105
2024-08-09 01:25:32,930 ERROR An error occured while setting the password: /home/frank/virtual_doctor_backend/models/base_model.py 12
Traceback (most recent call last):
  File "/home/frank/virtual_doctor_backend/models/base_model.py", line 9, in set_pwd
    self.password = bcrypt.hashpw(password.encode('UTF-8'), bcrypt.gensalt())
AttributeError: 'int' object has no attribute 'encode'
2024-08-09 01:25:33,217 ERROR File for hospital not saved: /home/frank/virtual_doctor_backend/api/auth.py 100
Traceback (most recent call last):
  File "/home/frank/virtual_doctor_backend/api/auth.py", line 98, in register
    pre_process_file(file, role, name)
  File "/home/frank/virtual_doctor_backend/api/utils.py", line 66, in pre_process_file
    filename = secure_filename(file.filename)
AttributeError: 'bytes' object has no attribute 'filename'
2024-08-09 01:31:22,826 INFO Logging setup successfully: /home/frank/virtual_doctor_backend/./app.py 32
2024-08-09 01:31:22,827 INFO Uploads directory set up successfully: /home/frank/virtual_doctor_backend/./app.py 50
NoneType: None
2024-08-09 01:31:22,827 INFO DataBase set up successfully: /home/frank/virtual_doctor_backend/./app.py 62
2024-08-09 01:31:23,068 INFO Migrations set up successfully: /home/frank/virtual_doctor_backend/./app.py 74
2024-08-09 01:31:23,132 INFO Blueprints registered successfully: /home/frank/virtual_doctor_backend/./app.py 82
2024-08-09 01:31:23,133 INFO Mail service setup successfully: /home/frank/virtual_doctor_backend/./app.py 95
2024-08-09 01:31:23,133 INFO App created successfully: /home/frank/virtual_doctor_backend/./app.py 105
2024-08-09 01:34:05,693 INFO Logging setup successfully: /home/frank/virtual_doctor_backend/./app.py 32
2024-08-09 01:34:05,694 INFO Uploads directory set up successfully: /home/frank/virtual_doctor_backend/./app.py 50
NoneType: None
2024-08-09 01:34:05,694 INFO DataBase set up successfully: /home/frank/virtual_doctor_backend/./app.py 62
2024-08-09 01:34:05,823 INFO Migrations set up successfully: /home/frank/virtual_doctor_backend/./app.py 74
2024-08-09 01:34:05,866 INFO Blueprints registered successfully: /home/frank/virtual_doctor_backend/./app.py 82
2024-08-09 01:34:05,867 INFO Mail service setup successfully: /home/frank/virtual_doctor_backend/./app.py 95
2024-08-09 01:34:05,867 INFO App created successfully: /home/frank/virtual_doctor_backend/./app.py 105
2024-08-09 01:35:39,423 ERROR An error occured while setting the password: /home/frank/virtual_doctor_backend/models/base_model.py 12
Traceback (most recent call last):
  File "/home/frank/virtual_doctor_backend/models/base_model.py", line 9, in set_pwd
    self.password = bcrypt.hashpw(password.encode('UTF-8'), bcrypt.gensalt())
AttributeError: 'int' object has no attribute 'encode'
2024-08-09 01:35:39,831 ERROR File for hospital not saved: /home/frank/virtual_doctor_backend/api/auth.py 100
Traceback (most recent call last):
  File "/home/frank/virtual_doctor_backend/api/auth.py", line 98, in register
    pre_process_file(file, role, name)
  File "/home/frank/virtual_doctor_backend/api/utils.py", line 68, in pre_process_file
    file.save(file_path)
  File "/home/frank/.local/lib/python3.10/site-packages/werkzeug/datastructures/file_storage.py", line 125, in save
    dst = open(dst, "wb")
FileNotFoundError: [Errno 2] No such file or directory: '/home/frank/virtual_doctor_backend/uploads/hospital/virtual doctor-Web_development_invoice_03_3.docx'
2024-08-09 01:39:58,816 INFO Logging setup successfully: /home/frank/virtual_doctor_backend/./app.py 32
2024-08-09 01:39:58,817 INFO Uploads directory set up successfully: /home/frank/virtual_doctor_backend/./app.py 50
NoneType: None
2024-08-09 01:39:58,819 INFO DataBase set up successfully: /home/frank/virtual_doctor_backend/./app.py 62
2024-08-09 01:39:59,149 INFO Migrations set up successfully: /home/frank/virtual_doctor_backend/./app.py 74
2024-08-09 01:39:59,236 INFO Blueprints registered successfully: /home/frank/virtual_doctor_backend/./app.py 82
2024-08-09 01:39:59,238 INFO Mail service setup successfully: /home/frank/virtual_doctor_backend/./app.py 95
2024-08-09 01:39:59,239 INFO App created successfully: /home/frank/virtual_doctor_backend/./app.py 105
2024-08-09 01:40:14,555 INFO Logging setup successfully: /home/frank/virtual_doctor_backend/./app.py 32
2024-08-09 01:40:14,556 INFO Uploads directory set up successfully: /home/frank/virtual_doctor_backend/./app.py 50
NoneType: None
2024-08-09 01:40:14,556 INFO DataBase set up successfully: /home/frank/virtual_doctor_backend/./app.py 62
2024-08-09 01:40:14,706 INFO Migrations set up successfully: /home/frank/virtual_doctor_backend/./app.py 74
2024-08-09 01:40:14,756 INFO Blueprints registered successfully: /home/frank/virtual_doctor_backend/./app.py 82
2024-08-09 01:40:14,757 INFO Mail service setup successfully: /home/frank/virtual_doctor_backend/./app.py 95
2024-08-09 01:40:14,757 INFO App created successfully: /home/frank/virtual_doctor_backend/./app.py 105
2024-08-09 01:42:02,751 ERROR An error occured while setting the password: /home/frank/virtual_doctor_backend/models/base_model.py 12
Traceback (most recent call last):
  File "/home/frank/virtual_doctor_backend/models/base_model.py", line 9, in set_pwd
    self.password = bcrypt.hashpw(password.encode('UTF-8'), bcrypt.gensalt())
AttributeError: 'int' object has no attribute 'encode'
2024-08-09 01:42:03,272 ERROR hospital registration failed: /home/frank/virtual_doctor_backend/api/auth.py 92
Traceback (most recent call last):
  File "/home/frank/.local/lib/python3.10/site-packages/sqlalchemy/engine/base.py", line 1970, in _exec_single_context
    self.dialect.do_execute(
  File "/home/frank/.local/lib/python3.10/site-packages/sqlalchemy/engine/default.py", line 924, in do_execute
    cursor.execute(statement, parameters)
  File "/home/frank/.local/lib/python3.10/site-packages/pymysql/cursors.py", line 153, in execute
    result = self._query(query)
  File "/home/frank/.local/lib/python3.10/site-packages/pymysql/cursors.py", line 322, in _query
    conn.query(q)
  File "/home/frank/.local/lib/python3.10/site-packages/pymysql/connections.py", line 563, in query
    self._affected_rows = self._read_query_result(unbuffered=unbuffered)
  File "/home/frank/.local/lib/python3.10/site-packages/pymysql/connections.py", line 825, in _read_query_result
    result.read()
  File "/home/frank/.local/lib/python3.10/site-packages/pymysql/connections.py", line 1199, in read
    first_packet = self.connection._read_packet()
  File "/home/frank/.local/lib/python3.10/site-packages/pymysql/connections.py", line 775, in _read_packet
    packet.raise_for_error()
  File "/home/frank/.local/lib/python3.10/site-packages/pymysql/protocol.py", line 219, in raise_for_error
    err.raise_mysql_exception(self._data)
  File "/home/frank/.local/lib/python3.10/site-packages/pymysql/err.py", line 150, in raise_mysql_exception
    raise errorclass(errno, errval)
pymysql.err.IntegrityError: (1062, "Duplicate entry '0783033211' for key 'hospitals.contact'")

The above exception was the direct cause of the following exception:

Traceback (most recent call last):
  File "/home/frank/virtual_doctor_backend/api/auth.py", line 89, in register
    db.session.commit()
  File "/home/frank/.local/lib/python3.10/site-packages/sqlalchemy/orm/scoping.py", line 597, in commit
    return self._proxied.commit()
  File "/home/frank/.local/lib/python3.10/site-packages/sqlalchemy/orm/session.py", line 1972, in commit
    trans.commit(_to_root=True)
  File "<string>", line 2, in commit
  File "/home/frank/.local/lib/python3.10/site-packages/sqlalchemy/orm/state_changes.py", line 139, in _go
    ret_value = fn(self, *arg, **kw)
  File "/home/frank/.local/lib/python3.10/site-packages/sqlalchemy/orm/session.py", line 1257, in commit
    self._prepare_impl()
  File "<string>", line 2, in _prepare_impl
  File "/home/frank/.local/lib/python3.10/site-packages/sqlalchemy/orm/state_changes.py", line 139, in _go
    ret_value = fn(self, *arg, **kw)
  File "/home/frank/.local/lib/python3.10/site-packages/sqlalchemy/orm/session.py", line 1232, in _prepare_impl
    self.session.flush()
  File "/home/frank/.local/lib/python3.10/site-packages/sqlalchemy/orm/session.py", line 4296, in flush
    self._flush(objects)
  File "/home/frank/.local/lib/python3.10/site-packages/sqlalchemy/orm/session.py", line 4431, in _flush
    with util.safe_reraise():
  File "/home/frank/.local/lib/python3.10/site-packages/sqlalchemy/util/langhelpers.py", line 146, in __exit__
    raise exc_value.with_traceback(exc_tb)
  File "/home/frank/.local/lib/python3.10/site-packages/sqlalchemy/orm/session.py", line 4392, in _flush
    flush_context.execute()
  File "/home/frank/.local/lib/python3.10/site-packages/sqlalchemy/orm/unitofwork.py", line 466, in execute
    rec.execute(self)
  File "/home/frank/.local/lib/python3.10/site-packages/sqlalchemy/orm/unitofwork.py", line 642, in execute
    util.preloaded.orm_persistence.save_obj(
  File "/home/frank/.local/lib/python3.10/site-packages/sqlalchemy/orm/persistence.py", line 93, in save_obj
    _emit_insert_statements(
  File "/home/frank/.local/lib/python3.10/site-packages/sqlalchemy/orm/persistence.py", line 1233, in _emit_insert_statements
    result = connection.execute(
  File "/home/frank/.local/lib/python3.10/site-packages/sqlalchemy/engine/base.py", line 1421, in execute
    return meth(
  File "/home/frank/.local/lib/python3.10/site-packages/sqlalchemy/sql/elements.py", line 514, in _execute_on_connection
    return connection._execute_clauseelement(
  File "/home/frank/.local/lib/python3.10/site-packages/sqlalchemy/engine/base.py", line 1643, in _execute_clauseelement
    ret = self._execute_context(
  File "/home/frank/.local/lib/python3.10/site-packages/sqlalchemy/engine/base.py", line 1849, in _execute_context
    return self._exec_single_context(
  File "/home/frank/.local/lib/python3.10/site-packages/sqlalchemy/engine/base.py", line 1989, in _exec_single_context
    self._handle_dbapi_exception(
  File "/home/frank/.local/lib/python3.10/site-packages/sqlalchemy/engine/base.py", line 2356, in _handle_dbapi_exception
    raise sqlalchemy_exception.with_traceback(exc_info[2]) from e
  File "/home/frank/.local/lib/python3.10/site-packages/sqlalchemy/engine/base.py", line 1970, in _exec_single_context
    self.dialect.do_execute(
  File "/home/frank/.local/lib/python3.10/site-packages/sqlalchemy/engine/default.py", line 924, in do_execute
    cursor.execute(statement, parameters)
  File "/home/frank/.local/lib/python3.10/site-packages/pymysql/cursors.py", line 153, in execute
    result = self._query(query)
  File "/home/frank/.local/lib/python3.10/site-packages/pymysql/cursors.py", line 322, in _query
    conn.query(q)
  File "/home/frank/.local/lib/python3.10/site-packages/pymysql/connections.py", line 563, in query
    self._affected_rows = self._read_query_result(unbuffered=unbuffered)
  File "/home/frank/.local/lib/python3.10/site-packages/pymysql/connections.py", line 825, in _read_query_result
    result.read()
  File "/home/frank/.local/lib/python3.10/site-packages/pymysql/connections.py", line 1199, in read
    first_packet = self.connection._read_packet()
  File "/home/frank/.local/lib/python3.10/site-packages/pymysql/connections.py", line 775, in _read_packet
    packet.raise_for_error()
  File "/home/frank/.local/lib/python3.10/site-packages/pymysql/protocol.py", line 219, in raise_for_error
    err.raise_mysql_exception(self._data)
  File "/home/frank/.local/lib/python3.10/site-packages/pymysql/err.py", line 150, in raise_mysql_exception
    raise errorclass(errno, errval)
sqlalchemy.exc.IntegrityError: (pymysql.err.IntegrityError) (1062, "Duplicate entry '0783033211' for key 'hospitals.contact'")
[SQL: INSERT INTO hospitals (hosp_uuid, hosp_name, hosp_address, contact, email, password, verification, reg_date) VALUES (%(hosp_uuid)s, %(hosp_name)s, %(hosp_address)s, %(contact)s, %(email)s, %(password)s, %(verification)s, %(reg_date)s)]
[parameters: {'hosp_uuid': 'd49fc490-3838-4306-972e-81541a67b671', 'hosp_name': 'virtual doctor', 'hosp_address': 'Ngong, Kajiado, Kenya', 'contact': '0783033211', 'email': 'frankchege698@gmail.com', 'password': None, 'verification': 'unverified', 'reg_date': None}]
(Background on this error at: https://sqlalche.me/e/20/gkpj)
2024-08-09 19:24:47,792 INFO Logging setup successfully: /home/frank/virtual_doctor_backend/./app.py 32
2024-08-09 19:24:47,820 INFO Uploads directory set up successfully: /home/frank/virtual_doctor_backend/./app.py 50
NoneType: None
2024-08-09 19:24:47,822 INFO DataBase set up successfully: /home/frank/virtual_doctor_backend/./app.py 62
2024-08-09 19:24:48,741 INFO Migrations set up successfully: /home/frank/virtual_doctor_backend/./app.py 74
2024-08-09 19:24:48,799 INFO Blueprints registered successfully: /home/frank/virtual_doctor_backend/./app.py 82
2024-08-09 19:24:48,800 INFO Mail service setup successfully: /home/frank/virtual_doctor_backend/./app.py 95
2024-08-09 19:24:48,801 INFO App created successfully: /home/frank/virtual_doctor_backend/./app.py 105
2024-08-09 19:24:51,650 INFO Logging setup successfully: /home/frank/virtual_doctor_backend/./app.py 32
2024-08-09 19:24:51,650 INFO Uploads directory set up successfully: /home/frank/virtual_doctor_backend/./app.py 50
NoneType: None
2024-08-09 19:24:51,651 INFO DataBase set up successfully: /home/frank/virtual_doctor_backend/./app.py 62
2024-08-09 19:24:51,774 INFO Migrations set up successfully: /home/frank/virtual_doctor_backend/./app.py 74
2024-08-09 19:24:51,807 INFO Blueprints registered successfully: /home/frank/virtual_doctor_backend/./app.py 82
2024-08-09 19:24:51,807 INFO Mail service setup successfully: /home/frank/virtual_doctor_backend/./app.py 95
2024-08-09 19:24:51,807 INFO App created successfully: /home/frank/virtual_doctor_backend/./app.py 105
2024-08-13 23:35:31,649 INFO Logging setup successfully: /home/frank/virtual_doctor_backend/./app.py 32
2024-08-13 23:35:31,650 INFO Uploads directory set up successfully: /home/frank/virtual_doctor_backend/./app.py 50
NoneType: None
2024-08-13 23:35:31,650 INFO DataBase set up successfully: /home/frank/virtual_doctor_backend/./app.py 62
2024-08-13 23:35:32,266 INFO Migrations set up successfully: /home/frank/virtual_doctor_backend/./app.py 74
2024-08-13 23:35:32,303 INFO Blueprints registered successfully: /home/frank/virtual_doctor_backend/./app.py 82
2024-08-13 23:35:32,304 INFO Mail service setup successfully: /home/frank/virtual_doctor_backend/./app.py 95
2024-08-13 23:35:32,304 INFO App created successfully: /home/frank/virtual_doctor_backend/./app.py 105
2024-08-13 23:35:33,696 INFO Logging setup successfully: /home/frank/virtual_doctor_backend/./app.py 32
2024-08-13 23:35:33,696 INFO Uploads directory set up successfully: /home/frank/virtual_doctor_backend/./app.py 50
NoneType: None
2024-08-13 23:35:33,696 INFO DataBase set up successfully: /home/frank/virtual_doctor_backend/./app.py 62
2024-08-13 23:35:33,779 INFO Migrations set up successfully: /home/frank/virtual_doctor_backend/./app.py 74
2024-08-13 23:35:33,810 INFO Blueprints registered successfully: /home/frank/virtual_doctor_backend/./app.py 82
2024-08-13 23:35:33,811 INFO Mail service setup successfully: /home/frank/virtual_doctor_backend/./app.py 95
2024-08-13 23:35:33,811 INFO App created successfully: /home/frank/virtual_doctor_backend/./app.py 105
2024-08-13 23:41:31,191 ERROR An error occured while setting the password: /home/frank/virtual_doctor_backend/models/base_model.py 12
Traceback (most recent call last):
  File "/home/frank/virtual_doctor_backend/models/base_model.py", line 9, in set_pwd
    self.password = bcrypt.hashpw(password.encode('UTF-8'), bcrypt.gensalt())
AttributeError: 'int' object has no attribute 'encode'
2024-08-13 23:41:32,242 ERROR File for hospital not saved: /home/frank/virtual_doctor_backend/api/auth.py 100
Traceback (most recent call last):
  File "/home/frank/virtual_doctor_backend/api/auth.py", line 98, in register
    pre_process_file(file, role, name)
  File "/home/frank/virtual_doctor_backend/api/utils.py", line 68, in pre_process_file
    file.save(file_path)
  File "/home/frank/.local/lib/python3.10/site-packages/werkzeug/datastructures/file_storage.py", line 125, in save
    dst = open(dst, "wb")
FileNotFoundError: [Errno 2] No such file or directory: '/home/frank/virtual_doctor_backend/uploads/hospital/Francis Chege-Web_development_invoice_03_3.docx'
2024-08-13 23:54:50,267 INFO Logging setup successfully: /home/frank/virtual_doctor_backend/./app.py 32
2024-08-13 23:54:50,267 INFO Uploads directory set up successfully: /home/frank/virtual_doctor_backend/./app.py 50
NoneType: None
2024-08-13 23:54:50,268 INFO DataBase set up successfully: /home/frank/virtual_doctor_backend/./app.py 62
2024-08-13 23:54:50,332 INFO Migrations set up successfully: /home/frank/virtual_doctor_backend/./app.py 74
2024-08-13 23:54:50,349 INFO Blueprints registered successfully: /home/frank/virtual_doctor_backend/./app.py 82
2024-08-13 23:54:50,349 INFO Mail service setup successfully: /home/frank/virtual_doctor_backend/./app.py 95
2024-08-13 23:54:50,349 INFO App created successfully: /home/frank/virtual_doctor_backend/./app.py 105
2024-08-13 23:59:52,922 INFO Logging setup successfully: /home/frank/virtual_doctor_backend/./app.py 32
2024-08-13 23:59:52,922 INFO Uploads directory set up successfully: /home/frank/virtual_doctor_backend/./app.py 50
NoneType: None
2024-08-13 23:59:52,923 INFO DataBase set up successfully: /home/frank/virtual_doctor_backend/./app.py 62
2024-08-13 23:59:53,003 INFO Migrations set up successfully: /home/frank/virtual_doctor_backend/./app.py 74
2024-08-13 23:59:53,026 INFO Blueprints registered successfully: /home/frank/virtual_doctor_backend/./app.py 82
2024-08-13 23:59:53,026 INFO Mail service setup successfully: /home/frank/virtual_doctor_backend/./app.py 95
2024-08-13 23:59:53,026 INFO App created successfully: /home/frank/virtual_doctor_backend/./app.py 105
2024-08-14 00:00:15,215 INFO Logging setup successfully: /home/frank/virtual_doctor_backend/./app.py 32
2024-08-14 00:00:15,215 INFO Uploads directory set up successfully: /home/frank/virtual_doctor_backend/./app.py 50
NoneType: None
2024-08-14 00:00:15,216 INFO DataBase set up successfully: /home/frank/virtual_doctor_backend/./app.py 62
2024-08-14 00:00:15,279 INFO Migrations set up successfully: /home/frank/virtual_doctor_backend/./app.py 74
2024-08-14 00:00:15,297 INFO Blueprints registered successfully: /home/frank/virtual_doctor_backend/./app.py 82
2024-08-14 00:00:15,297 INFO Mail service setup successfully: /home/frank/virtual_doctor_backend/./app.py 95
2024-08-14 00:00:15,297 INFO App created successfully: /home/frank/virtual_doctor_backend/./app.py 105
2024-08-14 00:01:10,901 ERROR hospital registration failed: /home/frank/virtual_doctor_backend/api/auth.py 92
Traceback (most recent call last):
  File "/home/frank/.local/lib/python3.10/site-packages/sqlalchemy/engine/base.py", line 1970, in _exec_single_context
    self.dialect.do_execute(
  File "/home/frank/.local/lib/python3.10/site-packages/sqlalchemy/engine/default.py", line 924, in do_execute
    cursor.execute(statement, parameters)
  File "/home/frank/.local/lib/python3.10/site-packages/pymysql/cursors.py", line 153, in execute
    result = self._query(query)
  File "/home/frank/.local/lib/python3.10/site-packages/pymysql/cursors.py", line 322, in _query
    conn.query(q)
  File "/home/frank/.local/lib/python3.10/site-packages/pymysql/connections.py", line 563, in query
    self._affected_rows = self._read_query_result(unbuffered=unbuffered)
  File "/home/frank/.local/lib/python3.10/site-packages/pymysql/connections.py", line 825, in _read_query_result
    result.read()
  File "/home/frank/.local/lib/python3.10/site-packages/pymysql/connections.py", line 1199, in read
    first_packet = self.connection._read_packet()
  File "/home/frank/.local/lib/python3.10/site-packages/pymysql/connections.py", line 775, in _read_packet
    packet.raise_for_error()
  File "/home/frank/.local/lib/python3.10/site-packages/pymysql/protocol.py", line 219, in raise_for_error
    err.raise_mysql_exception(self._data)
  File "/home/frank/.local/lib/python3.10/site-packages/pymysql/err.py", line 150, in raise_mysql_exception
    raise errorclass(errno, errval)
pymysql.err.IntegrityError: (1062, "Duplicate entry '0712750179' for key 'hospitals.contact'")

The above exception was the direct cause of the following exception:

Traceback (most recent call last):
  File "/home/frank/virtual_doctor_backend/api/auth.py", line 89, in register
    db.session.commit()
  File "/home/frank/.local/lib/python3.10/site-packages/sqlalchemy/orm/scoping.py", line 597, in commit
    return self._proxied.commit()
  File "/home/frank/.local/lib/python3.10/site-packages/sqlalchemy/orm/session.py", line 1972, in commit
    trans.commit(_to_root=True)
  File "<string>", line 2, in commit
  File "/home/frank/.local/lib/python3.10/site-packages/sqlalchemy/orm/state_changes.py", line 139, in _go
    ret_value = fn(self, *arg, **kw)
  File "/home/frank/.local/lib/python3.10/site-packages/sqlalchemy/orm/session.py", line 1257, in commit
    self._prepare_impl()
  File "<string>", line 2, in _prepare_impl
  File "/home/frank/.local/lib/python3.10/site-packages/sqlalchemy/orm/state_changes.py", line 139, in _go
    ret_value = fn(self, *arg, **kw)
  File "/home/frank/.local/lib/python3.10/site-packages/sqlalchemy/orm/session.py", line 1232, in _prepare_impl
    self.session.flush()
  File "/home/frank/.local/lib/python3.10/site-packages/sqlalchemy/orm/session.py", line 4296, in flush
    self._flush(objects)
  File "/home/frank/.local/lib/python3.10/site-packages/sqlalchemy/orm/session.py", line 4431, in _flush
    with util.safe_reraise():
  File "/home/frank/.local/lib/python3.10/site-packages/sqlalchemy/util/langhelpers.py", line 146, in __exit__
    raise exc_value.with_traceback(exc_tb)
  File "/home/frank/.local/lib/python3.10/site-packages/sqlalchemy/orm/session.py", line 4392, in _flush
    flush_context.execute()
  File "/home/frank/.local/lib/python3.10/site-packages/sqlalchemy/orm/unitofwork.py", line 466, in execute
    rec.execute(self)
  File "/home/frank/.local/lib/python3.10/site-packages/sqlalchemy/orm/unitofwork.py", line 642, in execute
    util.preloaded.orm_persistence.save_obj(
  File "/home/frank/.local/lib/python3.10/site-packages/sqlalchemy/orm/persistence.py", line 93, in save_obj
    _emit_insert_statements(
  File "/home/frank/.local/lib/python3.10/site-packages/sqlalchemy/orm/persistence.py", line 1233, in _emit_insert_statements
    result = connection.execute(
  File "/home/frank/.local/lib/python3.10/site-packages/sqlalchemy/engine/base.py", line 1421, in execute
    return meth(
  File "/home/frank/.local/lib/python3.10/site-packages/sqlalchemy/sql/elements.py", line 514, in _execute_on_connection
    return connection._execute_clauseelement(
  File "/home/frank/.local/lib/python3.10/site-packages/sqlalchemy/engine/base.py", line 1643, in _execute_clauseelement
    ret = self._execute_context(
  File "/home/frank/.local/lib/python3.10/site-packages/sqlalchemy/engine/base.py", line 1849, in _execute_context
    return self._exec_single_context(
  File "/home/frank/.local/lib/python3.10/site-packages/sqlalchemy/engine/base.py", line 1989, in _exec_single_context
    self._handle_dbapi_exception(
  File "/home/frank/.local/lib/python3.10/site-packages/sqlalchemy/engine/base.py", line 2356, in _handle_dbapi_exception
    raise sqlalchemy_exception.with_traceback(exc_info[2]) from e
  File "/home/frank/.local/lib/python3.10/site-packages/sqlalchemy/engine/base.py", line 1970, in _exec_single_context
    self.dialect.do_execute(
  File "/home/frank/.local/lib/python3.10/site-packages/sqlalchemy/engine/default.py", line 924, in do_execute
    cursor.execute(statement, parameters)
  File "/home/frank/.local/lib/python3.10/site-packages/pymysql/cursors.py", line 153, in execute
    result = self._query(query)
  File "/home/frank/.local/lib/python3.10/site-packages/pymysql/cursors.py", line 322, in _query
    conn.query(q)
  File "/home/frank/.local/lib/python3.10/site-packages/pymysql/connections.py", line 563, in query
    self._affected_rows = self._read_query_result(unbuffered=unbuffered)
  File "/home/frank/.local/lib/python3.10/site-packages/pymysql/connections.py", line 825, in _read_query_result
    result.read()
  File "/home/frank/.local/lib/python3.10/site-packages/pymysql/connections.py", line 1199, in read
    first_packet = self.connection._read_packet()
  File "/home/frank/.local/lib/python3.10/site-packages/pymysql/connections.py", line 775, in _read_packet
    packet.raise_for_error()
  File "/home/frank/.local/lib/python3.10/site-packages/pymysql/protocol.py", line 219, in raise_for_error
    err.raise_mysql_exception(self._data)
  File "/home/frank/.local/lib/python3.10/site-packages/pymysql/err.py", line 150, in raise_mysql_exception
    raise errorclass(errno, errval)
sqlalchemy.exc.IntegrityError: (pymysql.err.IntegrityError) (1062, "Duplicate entry '0712750179' for key 'hospitals.contact'")
[SQL: INSERT INTO hospitals (hosp_uuid, hosp_name, hosp_address, contact, email, password, verification, reg_date) VALUES (%(hosp_uuid)s, %(hosp_name)s, %(hosp_address)s, %(contact)s, %(email)s, %(password)s, %(verification)s, %(reg_date)s)]
[parameters: {'hosp_uuid': 'bd2d3bfe-26b3-4f49-83fb-d0c71c3217df', 'hosp_name': 'Francis Chege', 'hosp_address': 'Ngong, Kajiado, Kenya', 'contact': '0712750179', 'email': 'francischege602@gmail.com', 'password': b'$2b$12$RDBkOIvL0K4YtCq55ANhgOvGnykYco0OEezTC.096gmiCu2l73EXm', 'verification': 'unverified', 'reg_date': None}]
(Background on this error at: https://sqlalche.me/e/20/gkpj)
2024-08-14 00:06:04,625 INFO Logging setup successfully: /home/frank/virtual_doctor_backend/./app.py 32
2024-08-14 00:06:04,625 INFO Uploads directory set up successfully: /home/frank/virtual_doctor_backend/./app.py 50
NoneType: None
2024-08-14 00:06:04,625 INFO DataBase set up successfully: /home/frank/virtual_doctor_backend/./app.py 62
2024-08-14 00:06:04,698 INFO Migrations set up successfully: /home/frank/virtual_doctor_backend/./app.py 74
2024-08-14 00:06:04,717 INFO Blueprints registered successfully: /home/frank/virtual_doctor_backend/./app.py 82
2024-08-14 00:06:04,717 INFO Mail service setup successfully: /home/frank/virtual_doctor_backend/./app.py 95
2024-08-14 00:06:04,717 INFO App created successfully: /home/frank/virtual_doctor_backend/./app.py 105
2024-08-14 00:06:08,148 INFO Logging setup successfully: /home/frank/virtual_doctor_backend/./app.py 32
2024-08-14 00:06:08,148 INFO Uploads directory set up successfully: /home/frank/virtual_doctor_backend/./app.py 50
NoneType: None
2024-08-14 00:06:08,149 INFO DataBase set up successfully: /home/frank/virtual_doctor_backend/./app.py 62
2024-08-14 00:06:08,221 INFO Migrations set up successfully: /home/frank/virtual_doctor_backend/./app.py 74
2024-08-14 00:06:08,243 INFO Blueprints registered successfully: /home/frank/virtual_doctor_backend/./app.py 82
2024-08-14 00:06:08,244 INFO Mail service setup successfully: /home/frank/virtual_doctor_backend/./app.py 95
2024-08-14 00:06:08,244 INFO App created successfully: /home/frank/virtual_doctor_backend/./app.py 105
2024-08-14 00:11:41,182 INFO Logging setup successfully: /home/frank/virtual_doctor_backend/./app.py 32
2024-08-14 00:11:41,182 INFO Uploads directory set up successfully: /home/frank/virtual_doctor_backend/./app.py 50
NoneType: None
2024-08-14 00:11:41,182 INFO DataBase set up successfully: /home/frank/virtual_doctor_backend/./app.py 62
2024-08-14 00:11:41,252 INFO Migrations set up successfully: /home/frank/virtual_doctor_backend/./app.py 74
2024-08-14 00:11:41,274 INFO Blueprints registered successfully: /home/frank/virtual_doctor_backend/./app.py 82
2024-08-14 00:11:41,274 INFO Mail service setup successfully: /home/frank/virtual_doctor_backend/./app.py 95
2024-08-14 00:11:41,274 INFO App created successfully: /home/frank/virtual_doctor_backend/./app.py 105
2024-08-14 00:13:51,580 INFO Logging setup successfully: /home/frank/virtual_doctor_backend/./app.py 32
2024-08-14 00:13:51,580 INFO Uploads directory set up successfully: /home/frank/virtual_doctor_backend/./app.py 50
NoneType: None
2024-08-14 00:13:51,581 INFO DataBase set up successfully: /home/frank/virtual_doctor_backend/./app.py 62
2024-08-14 00:13:51,643 INFO Migrations set up successfully: /home/frank/virtual_doctor_backend/./app.py 74
2024-08-14 00:13:51,658 INFO Blueprints registered successfully: /home/frank/virtual_doctor_backend/./app.py 82
2024-08-14 00:13:51,659 INFO Mail service setup successfully: /home/frank/virtual_doctor_backend/./app.py 95
2024-08-14 00:13:51,659 INFO App created successfully: /home/frank/virtual_doctor_backend/./app.py 105
2024-08-14 00:18:50,206 INFO Logging setup successfully: /home/frank/virtual_doctor_backend/app.py 32
2024-08-14 00:18:50,207 INFO Uploads directory set up successfully: /home/frank/virtual_doctor_backend/app.py 50
NoneType: None
2024-08-14 00:18:50,208 INFO DataBase set up successfully: /home/frank/virtual_doctor_backend/app.py 62
2024-08-14 00:18:50,296 INFO Migrations set up successfully: /home/frank/virtual_doctor_backend/app.py 74
2024-08-14 00:18:50,317 INFO Blueprints registered successfully: /home/frank/virtual_doctor_backend/app.py 82
2024-08-14 00:18:50,317 INFO Mail service setup successfully: /home/frank/virtual_doctor_backend/app.py 95
2024-08-14 00:18:50,318 INFO App created successfully: /home/frank/virtual_doctor_backend/app.py 105
