2024-10-24 12:09:15,999 WARNING Error fetching tasks: /home/frank/eazy_manage_backend/api/v1/routes/tasks.py 68
Traceback (most recent call last):
  File "/home/frank/eazy_manage_backend/api/v1/routes/tasks.py", line 57, in get_tasks
    serialized_data = [
  File "/home/frank/eazy_manage_backend/api/v1/routes/tasks.py", line 61, in <listcomp>
    'first_name': (lambda task : task[2].to_dict()).first_name,
AttributeError: 'function' object has no attribute 'first_name'
2024-10-24 12:09:21,286 WARNING Error fetching tasks: /home/frank/eazy_manage_backend/api/v1/routes/tasks.py 68
Traceback (most recent call last):
  File "/home/frank/eazy_manage_backend/api/v1/routes/tasks.py", line 57, in get_tasks
    serialized_data = [
  File "/home/frank/eazy_manage_backend/api/v1/routes/tasks.py", line 61, in <listcomp>
    'first_name': (lambda task : task[2].to_dict()).first_name,
AttributeError: 'function' object has no attribute 'first_name'
2024-10-24 12:14:47,179 INFO Logging setup successfully: /home/frank/eazy_manage_backend/./app.py 43
2024-10-24 12:14:47,180 INFO DataBase set up successfully: /home/frank/eazy_manage_backend/./app.py 55
2024-10-24 12:14:47,655 INFO database set up successfully: /home/frank/eazy_manage_backend/./app.py 60
2024-10-24 12:14:47,663 INFO Migrations set up successfully: /home/frank/eazy_manage_backend/./app.py 68
2024-10-24 12:14:47,676 INFO Blueprints registered successfully: /home/frank/eazy_manage_backend/./app.py 76
2024-10-24 12:14:47,676 INFO Mail service setup successfully: /home/frank/eazy_manage_backend/./app.py 89
2024-10-24 12:14:47,676 INFO App created successfully: /home/frank/eazy_manage_backend/./app.py 99
2024-10-24 12:14:49,215 WARNING Error fetching tasks: /home/frank/eazy_manage_backend/api/v1/routes/tasks.py 68
Traceback (most recent call last):
  File "/home/frank/eazy_manage_backend/api/v1/routes/tasks.py", line 57, in get_tasks
    serialized_data = [
  File "/home/frank/eazy_manage_backend/api/v1/routes/tasks.py", line 61, in <listcomp>
    'first_name': (task[2].to_dict()).first_name,
AttributeError: 'dict' object has no attribute 'first_name'
2024-10-24 12:14:52,022 WARNING Error fetching tasks: /home/frank/eazy_manage_backend/api/v1/routes/tasks.py 68
Traceback (most recent call last):
  File "/home/frank/eazy_manage_backend/api/v1/routes/tasks.py", line 57, in get_tasks
    serialized_data = [
  File "/home/frank/eazy_manage_backend/api/v1/routes/tasks.py", line 61, in <listcomp>
    'first_name': (task[2].to_dict()).first_name,
AttributeError: 'dict' object has no attribute 'first_name'
2024-10-24 12:15:58,760 INFO Logging setup successfully: /home/frank/eazy_manage_backend/./app.py 43
2024-10-24 12:15:58,760 INFO DataBase set up successfully: /home/frank/eazy_manage_backend/./app.py 55
2024-10-24 12:15:58,880 INFO database set up successfully: /home/frank/eazy_manage_backend/./app.py 60
2024-10-24 12:15:58,885 INFO Migrations set up successfully: /home/frank/eazy_manage_backend/./app.py 68
2024-10-24 12:15:58,897 INFO Blueprints registered successfully: /home/frank/eazy_manage_backend/./app.py 76
2024-10-24 12:15:58,897 INFO Mail service setup successfully: /home/frank/eazy_manage_backend/./app.py 89
2024-10-24 12:15:58,897 INFO App created successfully: /home/frank/eazy_manage_backend/./app.py 99
2024-10-24 12:16:43,219 INFO Logging setup successfully: /home/frank/eazy_manage_backend/./app.py 43
2024-10-24 12:16:43,220 INFO DataBase set up successfully: /home/frank/eazy_manage_backend/./app.py 55
2024-10-24 12:16:43,769 INFO database set up successfully: /home/frank/eazy_manage_backend/./app.py 60
2024-10-24 12:16:43,792 INFO Migrations set up successfully: /home/frank/eazy_manage_backend/./app.py 68
2024-10-24 12:16:43,815 INFO Blueprints registered successfully: /home/frank/eazy_manage_backend/./app.py 76
2024-10-24 12:16:43,815 INFO Mail service setup successfully: /home/frank/eazy_manage_backend/./app.py 89
2024-10-24 12:16:43,816 INFO App created successfully: /home/frank/eazy_manage_backend/./app.py 99
2024-10-24 12:16:45,224 WARNING Error fetching tasks: /home/frank/eazy_manage_backend/api/v1/routes/tasks.py 68
Traceback (most recent call last):
  File "/home/frank/eazy_manage_backend/api/v1/routes/tasks.py", line 57, in get_tasks
    serialized_data = [
  File "/home/frank/eazy_manage_backend/api/v1/routes/tasks.py", line 61, in <listcomp>
    'first_name': task[2].to_dict().first_name,
AttributeError: 'dict' object has no attribute 'first_name'
2024-10-24 12:16:46,858 WARNING Error fetching tasks: /home/frank/eazy_manage_backend/api/v1/routes/tasks.py 68
Traceback (most recent call last):
  File "/home/frank/eazy_manage_backend/api/v1/routes/tasks.py", line 57, in get_tasks
    serialized_data = [
  File "/home/frank/eazy_manage_backend/api/v1/routes/tasks.py", line 61, in <listcomp>
    'first_name': task[2].to_dict().first_name,
AttributeError: 'dict' object has no attribute 'first_name'
2024-10-24 12:17:06,077 INFO Logging setup successfully: /home/frank/eazy_manage_backend/./app.py 43
2024-10-24 12:17:06,078 INFO DataBase set up successfully: /home/frank/eazy_manage_backend/./app.py 55
2024-10-24 12:17:06,128 INFO database set up successfully: /home/frank/eazy_manage_backend/./app.py 60
2024-10-24 12:17:06,130 INFO Migrations set up successfully: /home/frank/eazy_manage_backend/./app.py 68
2024-10-24 12:17:06,136 INFO Blueprints registered successfully: /home/frank/eazy_manage_backend/./app.py 76
2024-10-24 12:17:06,136 INFO Mail service setup successfully: /home/frank/eazy_manage_backend/./app.py 89
2024-10-24 12:17:06,137 INFO App created successfully: /home/frank/eazy_manage_backend/./app.py 99
2024-10-24 12:19:09,745 INFO Logging setup successfully: /home/frank/eazy_manage_backend/./app.py 43
2024-10-24 12:19:09,745 INFO DataBase set up successfully: /home/frank/eazy_manage_backend/./app.py 55
2024-10-24 12:19:09,803 INFO database set up successfully: /home/frank/eazy_manage_backend/./app.py 60
2024-10-24 12:19:09,806 INFO Migrations set up successfully: /home/frank/eazy_manage_backend/./app.py 68
2024-10-24 12:19:09,811 INFO Blueprints registered successfully: /home/frank/eazy_manage_backend/./app.py 76
2024-10-24 12:19:09,812 INFO Mail service setup successfully: /home/frank/eazy_manage_backend/./app.py 89
2024-10-24 12:19:09,812 INFO App created successfully: /home/frank/eazy_manage_backend/./app.py 99
2024-10-24 12:19:14,350 WARNING Error fetching tasks: /home/frank/eazy_manage_backend/api/v1/routes/tasks.py 68
Traceback (most recent call last):
  File "/home/frank/eazy_manage_backend/api/v1/routes/tasks.py", line 57, in get_tasks
    serialized_data = [
  File "/home/frank/eazy_manage_backend/api/v1/routes/tasks.py", line 61, in <listcomp>
    'first_name': task[2].first_name.to_dict(),
AttributeError: 'str' object has no attribute 'to_dict'
2024-10-24 12:19:15,865 WARNING Error fetching tasks: /home/frank/eazy_manage_backend/api/v1/routes/tasks.py 68
Traceback (most recent call last):
  File "/home/frank/eazy_manage_backend/api/v1/routes/tasks.py", line 57, in get_tasks
    serialized_data = [
  File "/home/frank/eazy_manage_backend/api/v1/routes/tasks.py", line 61, in <listcomp>
    'first_name': task[2].first_name.to_dict(),
AttributeError: 'str' object has no attribute 'to_dict'
2024-10-24 12:20:03,730 INFO Logging setup successfully: /home/frank/eazy_manage_backend/./app.py 43
2024-10-24 12:20:03,730 INFO DataBase set up successfully: /home/frank/eazy_manage_backend/./app.py 55
2024-10-24 12:20:03,826 INFO database set up successfully: /home/frank/eazy_manage_backend/./app.py 60
2024-10-24 12:20:03,830 INFO Migrations set up successfully: /home/frank/eazy_manage_backend/./app.py 68
2024-10-24 12:20:03,836 INFO Blueprints registered successfully: /home/frank/eazy_manage_backend/./app.py 76
2024-10-24 12:20:03,837 INFO Mail service setup successfully: /home/frank/eazy_manage_backend/./app.py 89
2024-10-24 12:20:03,837 INFO App created successfully: /home/frank/eazy_manage_backend/./app.py 99
2024-10-24 12:21:02,893 INFO Logging setup successfully: /home/frank/eazy_manage_backend/./app.py 43
2024-10-24 12:21:02,894 INFO DataBase set up successfully: /home/frank/eazy_manage_backend/./app.py 55
2024-10-24 12:21:03,194 INFO database set up successfully: /home/frank/eazy_manage_backend/./app.py 60
2024-10-24 12:21:03,208 INFO Migrations set up successfully: /home/frank/eazy_manage_backend/./app.py 68
2024-10-24 12:21:03,244 INFO Blueprints registered successfully: /home/frank/eazy_manage_backend/./app.py 76
2024-10-24 12:21:03,245 INFO Mail service setup successfully: /home/frank/eazy_manage_backend/./app.py 89
2024-10-24 12:21:03,245 INFO App created successfully: /home/frank/eazy_manage_backend/./app.py 99
2024-10-24 12:21:52,007 INFO Logging setup successfully: /home/frank/eazy_manage_backend/./app.py 43
2024-10-24 12:21:52,008 INFO DataBase set up successfully: /home/frank/eazy_manage_backend/./app.py 55
2024-10-24 12:21:52,292 INFO database set up successfully: /home/frank/eazy_manage_backend/./app.py 60
2024-10-24 12:21:52,298 INFO Migrations set up successfully: /home/frank/eazy_manage_backend/./app.py 68
2024-10-24 12:21:52,314 INFO Blueprints registered successfully: /home/frank/eazy_manage_backend/./app.py 76
2024-10-24 12:21:52,314 INFO Mail service setup successfully: /home/frank/eazy_manage_backend/./app.py 89
2024-10-24 12:21:52,315 INFO App created successfully: /home/frank/eazy_manage_backend/./app.py 99
2024-10-24 12:26:29,126 INFO Logging setup successfully: /home/frank/eazy_manage_backend/./app.py 43
2024-10-24 12:26:29,127 INFO DataBase set up successfully: /home/frank/eazy_manage_backend/./app.py 55
2024-10-24 12:26:29,517 INFO database set up successfully: /home/frank/eazy_manage_backend/./app.py 60
2024-10-24 12:26:29,526 INFO Migrations set up successfully: /home/frank/eazy_manage_backend/./app.py 68
2024-10-24 12:26:29,551 INFO Blueprints registered successfully: /home/frank/eazy_manage_backend/./app.py 76
2024-10-24 12:26:29,552 INFO Mail service setup successfully: /home/frank/eazy_manage_backend/./app.py 89
2024-10-24 12:26:29,552 INFO App created successfully: /home/frank/eazy_manage_backend/./app.py 99
2024-10-24 20:38:02,245 INFO Logging setup successfully: /home/frank/eazy_manage_backend/./app.py 43
2024-10-24 20:38:02,291 INFO DataBase set up successfully: /home/frank/eazy_manage_backend/./app.py 55
2024-10-24 20:38:02,879 INFO database set up successfully: /home/frank/eazy_manage_backend/./app.py 60
2024-10-24 20:38:02,886 INFO Migrations set up successfully: /home/frank/eazy_manage_backend/./app.py 68
2024-10-24 20:38:02,899 INFO Blueprints registered successfully: /home/frank/eazy_manage_backend/./app.py 76
2024-10-24 20:38:02,899 INFO Mail service setup successfully: /home/frank/eazy_manage_backend/./app.py 89
2024-10-24 20:38:02,900 INFO App created successfully: /home/frank/eazy_manage_backend/./app.py 99
2024-10-24 20:38:03,856 INFO Logging setup successfully: /home/frank/eazy_manage_backend/./app.py 43
2024-10-24 20:38:03,857 INFO DataBase set up successfully: /home/frank/eazy_manage_backend/./app.py 55
2024-10-24 20:38:04,030 INFO database set up successfully: /home/frank/eazy_manage_backend/./app.py 60
2024-10-24 20:38:04,037 INFO Migrations set up successfully: /home/frank/eazy_manage_backend/./app.py 68
2024-10-24 20:38:04,046 INFO Blueprints registered successfully: /home/frank/eazy_manage_backend/./app.py 76
2024-10-24 20:38:04,047 INFO Mail service setup successfully: /home/frank/eazy_manage_backend/./app.py 89
2024-10-24 20:38:04,047 INFO App created successfully: /home/frank/eazy_manage_backend/./app.py 99
2024-10-24 21:52:06,955 WARNING Error fetching tasks: /home/frank/eazy_manage_backend/api/v1/routes/tasks.py 69
Traceback (most recent call last):
  File "/home/frank/.local/lib/python3.10/site-packages/sqlalchemy/engine/base.py", line 1970, in _exec_single_context
    self.dialect.do_execute(
  File "/home/frank/.local/lib/python3.10/site-packages/sqlalchemy/engine/default.py", line 924, in do_execute
    cursor.execute(statement, parameters)
  File "/home/frank/.local/lib/python3.10/site-packages/pymysql/cursors.py", line 153, in execute
    result = self._query(query)
  File "/home/frank/.local/lib/python3.10/site-packages/pymysql/cursors.py", line 322, in _query
    conn.query(q)
  File "/home/frank/.local/lib/python3.10/site-packages/pymysql/connections.py", line 563, in query
    self._affected_rows = self._read_query_result(unbuffered=unbuffered)
  File "/home/frank/.local/lib/python3.10/site-packages/pymysql/connections.py", line 825, in _read_query_result
    result.read()
  File "/home/frank/.local/lib/python3.10/site-packages/pymysql/connections.py", line 1199, in read
    first_packet = self.connection._read_packet()
  File "/home/frank/.local/lib/python3.10/site-packages/pymysql/connections.py", line 775, in _read_packet
    packet.raise_for_error()
  File "/home/frank/.local/lib/python3.10/site-packages/pymysql/protocol.py", line 219, in raise_for_error
    err.raise_mysql_exception(self._data)
  File "/home/frank/.local/lib/python3.10/site-packages/pymysql/err.py", line 150, in raise_mysql_exception
    raise errorclass(errno, errval)
pymysql.err.OperationalError: (1241, 'Operand should contain 1 column(s)')

The above exception was the direct cause of the following exception:

Traceback (most recent call last):
  File "/home/frank/eazy_manage_backend/api/v1/routes/tasks.py", line 51, in get_tasks
    tasks = query.offset(offset).limit(limit).all()
  File "/home/frank/.local/lib/python3.10/site-packages/sqlalchemy/orm/query.py", line 2673, in all
    return self._iter().all()  # type: ignore
  File "/home/frank/.local/lib/python3.10/site-packages/sqlalchemy/orm/query.py", line 2827, in _iter
    result: Union[ScalarResult[_T], Result[_T]] = self.session.execute(
  File "/home/frank/.local/lib/python3.10/site-packages/sqlalchemy/orm/session.py", line 2306, in execute
    return self._execute_internal(
  File "/home/frank/.local/lib/python3.10/site-packages/sqlalchemy/orm/session.py", line 2191, in _execute_internal
    result: Result[Any] = compile_state_cls.orm_execute_statement(
  File "/home/frank/.local/lib/python3.10/site-packages/sqlalchemy/orm/context.py", line 293, in orm_execute_statement
    result = conn.execute(
  File "/home/frank/.local/lib/python3.10/site-packages/sqlalchemy/engine/base.py", line 1421, in execute
    return meth(
  File "/home/frank/.local/lib/python3.10/site-packages/sqlalchemy/sql/elements.py", line 514, in _execute_on_connection
    return connection._execute_clauseelement(
  File "/home/frank/.local/lib/python3.10/site-packages/sqlalchemy/engine/base.py", line 1643, in _execute_clauseelement
    ret = self._execute_context(
  File "/home/frank/.local/lib/python3.10/site-packages/sqlalchemy/engine/base.py", line 1849, in _execute_context
    return self._exec_single_context(
  File "/home/frank/.local/lib/python3.10/site-packages/sqlalchemy/engine/base.py", line 1989, in _exec_single_context
    self._handle_dbapi_exception(
  File "/home/frank/.local/lib/python3.10/site-packages/sqlalchemy/engine/base.py", line 2356, in _handle_dbapi_exception
    raise sqlalchemy_exception.with_traceback(exc_info[2]) from e
  File "/home/frank/.local/lib/python3.10/site-packages/sqlalchemy/engine/base.py", line 1970, in _exec_single_context
    self.dialect.do_execute(
  File "/home/frank/.local/lib/python3.10/site-packages/sqlalchemy/engine/default.py", line 924, in do_execute
    cursor.execute(statement, parameters)
  File "/home/frank/.local/lib/python3.10/site-packages/pymysql/cursors.py", line 153, in execute
    result = self._query(query)
  File "/home/frank/.local/lib/python3.10/site-packages/pymysql/cursors.py", line 322, in _query
    conn.query(q)
  File "/home/frank/.local/lib/python3.10/site-packages/pymysql/connections.py", line 563, in query
    self._affected_rows = self._read_query_result(unbuffered=unbuffered)
  File "/home/frank/.local/lib/python3.10/site-packages/pymysql/connections.py", line 825, in _read_query_result
    result.read()
  File "/home/frank/.local/lib/python3.10/site-packages/pymysql/connections.py", line 1199, in read
    first_packet = self.connection._read_packet()
  File "/home/frank/.local/lib/python3.10/site-packages/pymysql/connections.py", line 775, in _read_packet
    packet.raise_for_error()
  File "/home/frank/.local/lib/python3.10/site-packages/pymysql/protocol.py", line 219, in raise_for_error
    err.raise_mysql_exception(self._data)
  File "/home/frank/.local/lib/python3.10/site-packages/pymysql/err.py", line 150, in raise_mysql_exception
    raise errorclass(errno, errval)
sqlalchemy.exc.OperationalError: (pymysql.err.OperationalError) (1241, 'Operand should contain 1 column(s)')
[SQL: SELECT count(*) OVER () AS total, tasks.task_id AS tasks_task_id, tasks.task_name AS tasks_task_name, tasks.description AS tasks_description, tasks.started AS tasks_started, tasks.to_end AS tasks_to_end, tasks.ended AS tasks_ended, tasks.priority AS tasks_priority, tasks.status AS tasks_status, tasks.notes AS tasks_notes, tasks.comments AS tasks_comments, tasks.user_id AS tasks_user_id 
FROM tasks 
WHERE tasks.user_id = %(user_id_1)s AND tasks.status = %(status_1)s AND (SELECT count(*) OVER () AS total, tasks.task_id, tasks.task_name, tasks.description, tasks.started, tasks.to_end, tasks.ended, tasks.priority, tasks.status, tasks.notes, tasks.comments, tasks.user_id 
FROM tasks 
WHERE tasks.user_id = %(user_id_1)s AND tasks.status = %(status_1)s AND tasks.ended >= %(ended_1)s AND tasks.ended <= %(ended_2)s) ORDER BY tasks.ended DESC 
 LIMIT %(param_1)s, %(param_2)s]
[parameters: {'user_id_1': '62a22a67-ee78-422e-b456-26d8a5963861', 'status_1': 'completed', 'ended_1': '2024-10-24', 'ended_2': '2024-10-31', 'param_1': 0, 'param_2': 20}]
(Background on this error at: https://sqlalche.me/e/20/e3q8)
2024-10-24 21:52:12,598 WARNING Error fetching tasks: /home/frank/eazy_manage_backend/api/v1/routes/tasks.py 69
Traceback (most recent call last):
  File "/home/frank/.local/lib/python3.10/site-packages/sqlalchemy/engine/base.py", line 1970, in _exec_single_context
    self.dialect.do_execute(
  File "/home/frank/.local/lib/python3.10/site-packages/sqlalchemy/engine/default.py", line 924, in do_execute
    cursor.execute(statement, parameters)
  File "/home/frank/.local/lib/python3.10/site-packages/pymysql/cursors.py", line 153, in execute
    result = self._query(query)
  File "/home/frank/.local/lib/python3.10/site-packages/pymysql/cursors.py", line 322, in _query
    conn.query(q)
  File "/home/frank/.local/lib/python3.10/site-packages/pymysql/connections.py", line 563, in query
    self._affected_rows = self._read_query_result(unbuffered=unbuffered)
  File "/home/frank/.local/lib/python3.10/site-packages/pymysql/connections.py", line 825, in _read_query_result
    result.read()
  File "/home/frank/.local/lib/python3.10/site-packages/pymysql/connections.py", line 1199, in read
    first_packet = self.connection._read_packet()
  File "/home/frank/.local/lib/python3.10/site-packages/pymysql/connections.py", line 775, in _read_packet
    packet.raise_for_error()
  File "/home/frank/.local/lib/python3.10/site-packages/pymysql/protocol.py", line 219, in raise_for_error
    err.raise_mysql_exception(self._data)
  File "/home/frank/.local/lib/python3.10/site-packages/pymysql/err.py", line 150, in raise_mysql_exception
    raise errorclass(errno, errval)
pymysql.err.OperationalError: (1241, 'Operand should contain 1 column(s)')

The above exception was the direct cause of the following exception:

Traceback (most recent call last):
  File "/home/frank/eazy_manage_backend/api/v1/routes/tasks.py", line 51, in get_tasks
    tasks = query.offset(offset).limit(limit).all()
  File "/home/frank/.local/lib/python3.10/site-packages/sqlalchemy/orm/query.py", line 2673, in all
    return self._iter().all()  # type: ignore
  File "/home/frank/.local/lib/python3.10/site-packages/sqlalchemy/orm/query.py", line 2827, in _iter
    result: Union[ScalarResult[_T], Result[_T]] = self.session.execute(
  File "/home/frank/.local/lib/python3.10/site-packages/sqlalchemy/orm/session.py", line 2306, in execute
    return self._execute_internal(
  File "/home/frank/.local/lib/python3.10/site-packages/sqlalchemy/orm/session.py", line 2191, in _execute_internal
    result: Result[Any] = compile_state_cls.orm_execute_statement(
  File "/home/frank/.local/lib/python3.10/site-packages/sqlalchemy/orm/context.py", line 293, in orm_execute_statement
    result = conn.execute(
  File "/home/frank/.local/lib/python3.10/site-packages/sqlalchemy/engine/base.py", line 1421, in execute
    return meth(
  File "/home/frank/.local/lib/python3.10/site-packages/sqlalchemy/sql/elements.py", line 514, in _execute_on_connection
    return connection._execute_clauseelement(
  File "/home/frank/.local/lib/python3.10/site-packages/sqlalchemy/engine/base.py", line 1643, in _execute_clauseelement
    ret = self._execute_context(
  File "/home/frank/.local/lib/python3.10/site-packages/sqlalchemy/engine/base.py", line 1849, in _execute_context
    return self._exec_single_context(
  File "/home/frank/.local/lib/python3.10/site-packages/sqlalchemy/engine/base.py", line 1989, in _exec_single_context
    self._handle_dbapi_exception(
  File "/home/frank/.local/lib/python3.10/site-packages/sqlalchemy/engine/base.py", line 2356, in _handle_dbapi_exception
    raise sqlalchemy_exception.with_traceback(exc_info[2]) from e
  File "/home/frank/.local/lib/python3.10/site-packages/sqlalchemy/engine/base.py", line 1970, in _exec_single_context
    self.dialect.do_execute(
  File "/home/frank/.local/lib/python3.10/site-packages/sqlalchemy/engine/default.py", line 924, in do_execute
    cursor.execute(statement, parameters)
  File "/home/frank/.local/lib/python3.10/site-packages/pymysql/cursors.py", line 153, in execute
    result = self._query(query)
  File "/home/frank/.local/lib/python3.10/site-packages/pymysql/cursors.py", line 322, in _query
    conn.query(q)
  File "/home/frank/.local/lib/python3.10/site-packages/pymysql/connections.py", line 563, in query
    self._affected_rows = self._read_query_result(unbuffered=unbuffered)
  File "/home/frank/.local/lib/python3.10/site-packages/pymysql/connections.py", line 825, in _read_query_result
    result.read()
  File "/home/frank/.local/lib/python3.10/site-packages/pymysql/connections.py", line 1199, in read
    first_packet = self.connection._read_packet()
  File "/home/frank/.local/lib/python3.10/site-packages/pymysql/connections.py", line 775, in _read_packet
    packet.raise_for_error()
  File "/home/frank/.local/lib/python3.10/site-packages/pymysql/protocol.py", line 219, in raise_for_error
    err.raise_mysql_exception(self._data)
  File "/home/frank/.local/lib/python3.10/site-packages/pymysql/err.py", line 150, in raise_mysql_exception
    raise errorclass(errno, errval)
sqlalchemy.exc.OperationalError: (pymysql.err.OperationalError) (1241, 'Operand should contain 1 column(s)')
[SQL: SELECT count(*) OVER () AS total, tasks.task_id AS tasks_task_id, tasks.task_name AS tasks_task_name, tasks.description AS tasks_description, tasks.started AS tasks_started, tasks.to_end AS tasks_to_end, tasks.ended AS tasks_ended, tasks.priority AS tasks_priority, tasks.status AS tasks_status, tasks.notes AS tasks_notes, tasks.comments AS tasks_comments, tasks.user_id AS tasks_user_id 
FROM tasks 
WHERE tasks.user_id = %(user_id_1)s AND tasks.status = %(status_1)s AND (SELECT count(*) OVER () AS total, tasks.task_id, tasks.task_name, tasks.description, tasks.started, tasks.to_end, tasks.ended, tasks.priority, tasks.status, tasks.notes, tasks.comments, tasks.user_id 
FROM tasks 
WHERE tasks.user_id = %(user_id_1)s AND tasks.status = %(status_1)s AND tasks.ended >= %(ended_1)s AND tasks.ended <= %(ended_2)s) ORDER BY tasks.ended DESC 
 LIMIT %(param_1)s, %(param_2)s]
[parameters: {'user_id_1': '62a22a67-ee78-422e-b456-26d8a5963861', 'status_1': 'completed', 'ended_1': '2024-10-24', 'ended_2': '2024-10-31', 'param_1': 0, 'param_2': 20}]
(Background on this error at: https://sqlalche.me/e/20/e3q8)
2024-10-24 22:51:13,314 INFO Logging setup successfully: /home/frank/eazy_manage_backend/app.py 43
2024-10-24 22:51:13,315 INFO DataBase set up successfully: /home/frank/eazy_manage_backend/app.py 55
2024-10-24 22:51:14,107 INFO database set up successfully: /home/frank/eazy_manage_backend/app.py 60
2024-10-24 22:51:14,108 INFO Migrations set up successfully: /home/frank/eazy_manage_backend/app.py 68
2024-10-24 22:51:14,129 INFO Blueprints registered successfully: /home/frank/eazy_manage_backend/app.py 76
2024-10-24 22:51:14,130 INFO Mail service setup successfully: /home/frank/eazy_manage_backend/app.py 89
2024-10-24 22:51:14,130 INFO App created successfully: /home/frank/eazy_manage_backend/app.py 99
2024-10-24 23:34:30,196 INFO Logging setup successfully: /home/frank/eazy_manage_backend/./app.py 43
2024-10-24 23:34:30,489 INFO DataBase set up successfully: /home/frank/eazy_manage_backend/./app.py 55
2024-10-24 23:34:38,198 INFO database set up successfully: /home/frank/eazy_manage_backend/./app.py 60
2024-10-24 23:34:38,264 INFO Migrations set up successfully: /home/frank/eazy_manage_backend/./app.py 68
2024-10-24 23:34:38,357 INFO Blueprints registered successfully: /home/frank/eazy_manage_backend/./app.py 76
2024-10-24 23:34:38,358 INFO Mail service setup successfully: /home/frank/eazy_manage_backend/./app.py 89
2024-10-24 23:34:38,364 INFO App created successfully: /home/frank/eazy_manage_backend/./app.py 99
2024-10-24 23:34:43,405 INFO Logging setup successfully: /home/frank/eazy_manage_backend/./app.py 43
2024-10-24 23:34:43,407 INFO DataBase set up successfully: /home/frank/eazy_manage_backend/./app.py 55
2024-10-24 23:34:43,589 INFO database set up successfully: /home/frank/eazy_manage_backend/./app.py 60
2024-10-24 23:34:43,600 INFO Migrations set up successfully: /home/frank/eazy_manage_backend/./app.py 68
2024-10-24 23:34:43,623 INFO Blueprints registered successfully: /home/frank/eazy_manage_backend/./app.py 76
2024-10-24 23:34:43,623 INFO Mail service setup successfully: /home/frank/eazy_manage_backend/./app.py 89
2024-10-24 23:34:43,624 INFO App created successfully: /home/frank/eazy_manage_backend/./app.py 99
2024-10-24 23:40:23,200 ERROR Schema error on register router, {'error': {'type': 'ValidationError', 'message': {'status': ['Invalid value.']}}}: /home/frank/eazy_manage_backend/api/v1/routes/auth.py 44
2024-10-24 23:40:53,917 ERROR Schema error on register router, {'error': {'type': 'ValidationError', 'message': {'status': ['Invalid value.']}}}: /home/frank/eazy_manage_backend/api/v1/routes/auth.py 44
2024-10-24 23:41:06,671 ERROR Schema error on register router, {'error': {'type': 'ValidationError', 'message': {'status': ['Invalid value.']}}}: /home/frank/eazy_manage_backend/api/v1/routes/auth.py 44
2024-10-24 23:41:17,890 INFO Logging setup successfully: /home/frank/eazy_manage_backend/app.py 43
2024-10-24 23:41:17,891 INFO DataBase set up successfully: /home/frank/eazy_manage_backend/app.py 55
2024-10-24 23:41:17,925 INFO database set up successfully: /home/frank/eazy_manage_backend/app.py 60
2024-10-24 23:41:17,926 INFO Migrations set up successfully: /home/frank/eazy_manage_backend/app.py 68
2024-10-24 23:41:17,947 INFO Blueprints registered successfully: /home/frank/eazy_manage_backend/app.py 76
2024-10-24 23:41:17,948 INFO Mail service setup successfully: /home/frank/eazy_manage_backend/app.py 89
2024-10-24 23:41:17,949 INFO App created successfully: /home/frank/eazy_manage_backend/app.py 99
2024-10-25 00:06:42,156 INFO Logging setup successfully: /home/frank/eazy_manage_backend/./app.py 43
2024-10-25 00:06:42,158 INFO DataBase set up successfully: /home/frank/eazy_manage_backend/./app.py 55
2024-10-25 00:06:42,293 INFO database set up successfully: /home/frank/eazy_manage_backend/./app.py 60
2024-10-25 00:06:42,303 INFO Migrations set up successfully: /home/frank/eazy_manage_backend/./app.py 68
2024-10-25 00:06:42,324 INFO Blueprints registered successfully: /home/frank/eazy_manage_backend/./app.py 76
2024-10-25 00:06:42,325 INFO Mail service setup successfully: /home/frank/eazy_manage_backend/./app.py 89
2024-10-25 00:06:42,325 INFO App created successfully: /home/frank/eazy_manage_backend/./app.py 99
2024-10-25 00:06:45,944 INFO Logging setup successfully: /home/frank/eazy_manage_backend/./app.py 43
2024-10-25 00:06:45,945 INFO DataBase set up successfully: /home/frank/eazy_manage_backend/./app.py 55
2024-10-25 00:06:46,084 INFO database set up successfully: /home/frank/eazy_manage_backend/./app.py 60
2024-10-25 00:06:46,090 INFO Migrations set up successfully: /home/frank/eazy_manage_backend/./app.py 68
2024-10-25 00:06:46,108 INFO Blueprints registered successfully: /home/frank/eazy_manage_backend/./app.py 76
2024-10-25 00:06:46,109 INFO Mail service setup successfully: /home/frank/eazy_manage_backend/./app.py 89
2024-10-25 00:06:46,109 INFO App created successfully: /home/frank/eazy_manage_backend/./app.py 99
2024-10-25 21:45:54,071 INFO Logging setup successfully: /home/frank/eazy_manage_backend/./app.py 44
2024-10-25 21:45:54,071 INFO DataBase set up successfully: /home/frank/eazy_manage_backend/./app.py 56
2024-10-25 21:45:54,185 INFO database set up successfully: /home/frank/eazy_manage_backend/./app.py 61
2024-10-25 21:45:54,191 INFO Migrations set up successfully: /home/frank/eazy_manage_backend/./app.py 69
2024-10-25 21:45:54,207 INFO Blueprints registered successfully: /home/frank/eazy_manage_backend/./app.py 77
2024-10-25 21:45:54,207 INFO Mail service setup successfully: /home/frank/eazy_manage_backend/./app.py 90
2024-10-25 21:45:54,208 INFO App created successfully: /home/frank/eazy_manage_backend/./app.py 100
2024-10-25 21:45:56,206 INFO Logging setup successfully: /home/frank/eazy_manage_backend/./app.py 44
2024-10-25 21:45:56,207 INFO DataBase set up successfully: /home/frank/eazy_manage_backend/./app.py 56
2024-10-25 21:45:56,307 INFO database set up successfully: /home/frank/eazy_manage_backend/./app.py 61
2024-10-25 21:45:56,313 INFO Migrations set up successfully: /home/frank/eazy_manage_backend/./app.py 69
2024-10-25 21:45:56,329 INFO Blueprints registered successfully: /home/frank/eazy_manage_backend/./app.py 77
2024-10-25 21:45:56,330 INFO Mail service setup successfully: /home/frank/eazy_manage_backend/./app.py 90
2024-10-25 21:45:56,330 INFO App created successfully: /home/frank/eazy_manage_backend/./app.py 100
2024-10-25 23:48:24,418 INFO Logging setup successfully: /home/frank/eazy_manage_backend/./app.py 44
2024-10-25 23:48:24,419 INFO DataBase set up successfully: /home/frank/eazy_manage_backend/./app.py 53
2024-10-25 23:48:24,420 WARNING database set up failed!: /home/frank/eazy_manage_backend/./app.py 60
Traceback (most recent call last):
  File "/home/frank/eazy_manage_backend/./app.py", line 54, in configure_app
    db.init_app(app)
  File "/home/frank/eazy_manage_backend/venv/lib/python3.10/site-packages/flask_sqlalchemy/extension.py", line 355, in init_app
    raise RuntimeError(
RuntimeError: Either 'SQLALCHEMY_DATABASE_URI' or 'SQLALCHEMY_BINDS' must be set.
2024-10-25 23:48:24,422 CRITICAL App was not created!: /home/frank/eazy_manage_backend/./app.py 99
Traceback (most recent call last):
  File "/home/frank/eazy_manage_backend/./app.py", line 96, in <module>
    app = configure_app(app)
  File "/home/frank/eazy_manage_backend/./app.py", line 54, in configure_app
    db.init_app(app)
  File "/home/frank/eazy_manage_backend/venv/lib/python3.10/site-packages/flask_sqlalchemy/extension.py", line 355, in init_app
    raise RuntimeError(
RuntimeError: Either 'SQLALCHEMY_DATABASE_URI' or 'SQLALCHEMY_BINDS' must be set.
2024-10-25 23:48:52,852 INFO Logging setup successfully: /home/frank/eazy_manage_backend/./app.py 44
2024-10-25 23:48:52,852 INFO DataBase set up successfully: /home/frank/eazy_manage_backend/./app.py 56
2024-10-25 23:48:52,887 WARNING database set up failed!: /home/frank/eazy_manage_backend/./app.py 63
Traceback (most recent call last):
  File "/home/frank/eazy_manage_backend/./app.py", line 57, in configure_app
    db.init_app(app)
  File "/home/frank/eazy_manage_backend/venv/lib/python3.10/site-packages/flask_sqlalchemy/extension.py", line 374, in init_app
    engines[key] = self._make_engine(key, options, app)
  File "/home/frank/eazy_manage_backend/venv/lib/python3.10/site-packages/flask_sqlalchemy/extension.py", line 665, in _make_engine
    return sa.engine_from_config(options, prefix="")
  File "/home/frank/eazy_manage_backend/venv/lib/python3.10/site-packages/sqlalchemy/engine/create.py", line 820, in engine_from_config
    return create_engine(url, **options)
  File "<string>", line 2, in create_engine
  File "/home/frank/eazy_manage_backend/venv/lib/python3.10/site-packages/sqlalchemy/util/deprecations.py", line 281, in warned
    return fn(*args, **kwargs)  # type: ignore[no-any-return]
  File "/home/frank/eazy_manage_backend/venv/lib/python3.10/site-packages/sqlalchemy/engine/create.py", line 599, in create_engine
    dbapi = dbapi_meth(**dbapi_args)
  File "/home/frank/eazy_manage_backend/venv/lib/python3.10/site-packages/sqlalchemy/dialects/mysql/pymysql.py", line 75, in import_dbapi
    return __import__("pymysql")
ModuleNotFoundError: No module named 'pymysql'
2024-10-25 23:48:52,889 CRITICAL App was not created!: /home/frank/eazy_manage_backend/./app.py 102
Traceback (most recent call last):
  File "/home/frank/eazy_manage_backend/./app.py", line 99, in <module>
    app = configure_app(app)
  File "/home/frank/eazy_manage_backend/./app.py", line 57, in configure_app
    db.init_app(app)
  File "/home/frank/eazy_manage_backend/venv/lib/python3.10/site-packages/flask_sqlalchemy/extension.py", line 374, in init_app
    engines[key] = self._make_engine(key, options, app)
  File "/home/frank/eazy_manage_backend/venv/lib/python3.10/site-packages/flask_sqlalchemy/extension.py", line 665, in _make_engine
    return sa.engine_from_config(options, prefix="")
  File "/home/frank/eazy_manage_backend/venv/lib/python3.10/site-packages/sqlalchemy/engine/create.py", line 820, in engine_from_config
    return create_engine(url, **options)
  File "<string>", line 2, in create_engine
  File "/home/frank/eazy_manage_backend/venv/lib/python3.10/site-packages/sqlalchemy/util/deprecations.py", line 281, in warned
    return fn(*args, **kwargs)  # type: ignore[no-any-return]
  File "/home/frank/eazy_manage_backend/venv/lib/python3.10/site-packages/sqlalchemy/engine/create.py", line 599, in create_engine
    dbapi = dbapi_meth(**dbapi_args)
  File "/home/frank/eazy_manage_backend/venv/lib/python3.10/site-packages/sqlalchemy/dialects/mysql/pymysql.py", line 75, in import_dbapi
    return __import__("pymysql")
ModuleNotFoundError: No module named 'pymysql'
2024-10-25 23:49:21,959 INFO Logging setup successfully: /home/frank/eazy_manage_backend/./app.py 44
2024-10-25 23:49:21,960 INFO DataBase set up successfully: /home/frank/eazy_manage_backend/./app.py 56
2024-10-25 23:49:22,054 INFO database set up successfully: /home/frank/eazy_manage_backend/./app.py 61
2024-10-25 23:49:22,060 INFO Migrations set up successfully: /home/frank/eazy_manage_backend/./app.py 69
2024-10-25 23:49:22,074 INFO Blueprints registered successfully: /home/frank/eazy_manage_backend/./app.py 77
2024-10-25 23:49:22,074 INFO Mail service setup successfully: /home/frank/eazy_manage_backend/./app.py 90
2024-10-25 23:49:22,075 INFO App created successfully: /home/frank/eazy_manage_backend/./app.py 100
2024-10-25 23:49:24,149 INFO Logging setup successfully: /home/frank/eazy_manage_backend/./app.py 44
2024-10-25 23:49:24,149 INFO DataBase set up successfully: /home/frank/eazy_manage_backend/./app.py 56
2024-10-25 23:49:24,271 INFO database set up successfully: /home/frank/eazy_manage_backend/./app.py 61
2024-10-25 23:49:24,277 INFO Migrations set up successfully: /home/frank/eazy_manage_backend/./app.py 69
2024-10-25 23:49:24,290 INFO Blueprints registered successfully: /home/frank/eazy_manage_backend/./app.py 77
2024-10-25 23:49:24,291 INFO Mail service setup successfully: /home/frank/eazy_manage_backend/./app.py 90
2024-10-25 23:49:24,291 INFO App created successfully: /home/frank/eazy_manage_backend/./app.py 100
