2024-10-13 21:58:57,828 INFO Logging setup successfully: /home/frank/eazy_manage_backend/./app.py 43
2024-10-13 21:58:57,829 INFO DataBase set up successfully: /home/frank/eazy_manage_backend/./app.py 55
2024-10-13 21:59:00,063 WARNING Migration set up failed!: /home/frank/eazy_manage_backend/./app.py 69
Traceback (most recent call last):
  File "/home/frank/.local/lib/python3.10/site-packages/sqlalchemy/engine/base.py", line 145, in __init__
    self._dbapi_connection = engine.raw_connection()
  File "/home/frank/.local/lib/python3.10/site-packages/sqlalchemy/engine/base.py", line 3303, in raw_connection
    return self.pool.connect()
  File "/home/frank/.local/lib/python3.10/site-packages/sqlalchemy/pool/base.py", line 449, in connect
    return _ConnectionFairy._checkout(self)
  File "/home/frank/.local/lib/python3.10/site-packages/sqlalchemy/pool/base.py", line 1263, in _checkout
    fairy = _ConnectionRecord.checkout(pool)
  File "/home/frank/.local/lib/python3.10/site-packages/sqlalchemy/pool/base.py", line 712, in checkout
    rec = pool._do_get()
  File "/home/frank/.local/lib/python3.10/site-packages/sqlalchemy/pool/impl.py", line 179, in _do_get
    with util.safe_reraise():
  File "/home/frank/.local/lib/python3.10/site-packages/sqlalchemy/util/langhelpers.py", line 146, in __exit__
    raise exc_value.with_traceback(exc_tb)
  File "/home/frank/.local/lib/python3.10/site-packages/sqlalchemy/pool/impl.py", line 177, in _do_get
    return self._create_connection()
  File "/home/frank/.local/lib/python3.10/site-packages/sqlalchemy/pool/base.py", line 390, in _create_connection
    return _ConnectionRecord(self)
  File "/home/frank/.local/lib/python3.10/site-packages/sqlalchemy/pool/base.py", line 674, in __init__
    self.__connect()
  File "/home/frank/.local/lib/python3.10/site-packages/sqlalchemy/pool/base.py", line 900, in __connect
    with util.safe_reraise():
  File "/home/frank/.local/lib/python3.10/site-packages/sqlalchemy/util/langhelpers.py", line 146, in __exit__
    raise exc_value.with_traceback(exc_tb)
  File "/home/frank/.local/lib/python3.10/site-packages/sqlalchemy/pool/base.py", line 896, in __connect
    self.dbapi_connection = connection = pool._invoke_creator(self)
  File "/home/frank/.local/lib/python3.10/site-packages/sqlalchemy/engine/create.py", line 643, in connect
    return dialect.connect(*cargs, **cparams)
  File "/home/frank/.local/lib/python3.10/site-packages/sqlalchemy/engine/default.py", line 616, in connect
    return self.loaded_dbapi.connect(*cargs, **cparams)
  File "/home/frank/.local/lib/python3.10/site-packages/pymysql/connections.py", line 361, in __init__
    self.connect()
  File "/home/frank/.local/lib/python3.10/site-packages/pymysql/connections.py", line 669, in connect
    self._request_authentication()
  File "/home/frank/.local/lib/python3.10/site-packages/pymysql/connections.py", line 979, in _request_authentication
    auth_packet = _auth.caching_sha2_password_auth(self, auth_packet)
  File "/home/frank/.local/lib/python3.10/site-packages/pymysql/_auth.py", line 268, in caching_sha2_password_auth
    pkt = _roundtrip(conn, data)
  File "/home/frank/.local/lib/python3.10/site-packages/pymysql/_auth.py", line 121, in _roundtrip
    pkt = conn._read_packet()
  File "/home/frank/.local/lib/python3.10/site-packages/pymysql/connections.py", line 775, in _read_packet
    packet.raise_for_error()
  File "/home/frank/.local/lib/python3.10/site-packages/pymysql/protocol.py", line 219, in raise_for_error
    err.raise_mysql_exception(self._data)
  File "/home/frank/.local/lib/python3.10/site-packages/pymysql/err.py", line 150, in raise_mysql_exception
    raise errorclass(errno, errval)
pymysql.err.OperationalError: (1049, "Unknown database 'eazy_manage'")

The above exception was the direct cause of the following exception:

Traceback (most recent call last):
  File "/home/frank/eazy_manage_backend/./app.py", line 65, in create_app
    db.create_all()
  File "/home/frank/.local/lib/python3.10/site-packages/flask_sqlalchemy/extension.py", line 900, in create_all
    self._call_for_binds(bind_key, "create_all")
  File "/home/frank/.local/lib/python3.10/site-packages/flask_sqlalchemy/extension.py", line 881, in _call_for_binds
    getattr(metadata, op_name)(bind=engine)
  File "/home/frank/.local/lib/python3.10/site-packages/sqlalchemy/sql/schema.py", line 5825, in create_all
    bind._run_ddl_visitor(
  File "/home/frank/.local/lib/python3.10/site-packages/sqlalchemy/engine/base.py", line 3253, in _run_ddl_visitor
    with self.begin() as conn:
  File "/usr/lib/python3.10/contextlib.py", line 135, in __enter__
    return next(self.gen)
  File "/home/frank/.local/lib/python3.10/site-packages/sqlalchemy/engine/base.py", line 3243, in begin
    with self.connect() as conn:
  File "/home/frank/.local/lib/python3.10/site-packages/sqlalchemy/engine/base.py", line 3279, in connect
    return self._connection_cls(self)
  File "/home/frank/.local/lib/python3.10/site-packages/sqlalchemy/engine/base.py", line 147, in __init__
    Connection._handle_dbapi_exception_noconnection(
  File "/home/frank/.local/lib/python3.10/site-packages/sqlalchemy/engine/base.py", line 2443, in _handle_dbapi_exception_noconnection
    raise sqlalchemy_exception.with_traceback(exc_info[2]) from e
  File "/home/frank/.local/lib/python3.10/site-packages/sqlalchemy/engine/base.py", line 145, in __init__
    self._dbapi_connection = engine.raw_connection()
  File "/home/frank/.local/lib/python3.10/site-packages/sqlalchemy/engine/base.py", line 3303, in raw_connection
    return self.pool.connect()
  File "/home/frank/.local/lib/python3.10/site-packages/sqlalchemy/pool/base.py", line 449, in connect
    return _ConnectionFairy._checkout(self)
  File "/home/frank/.local/lib/python3.10/site-packages/sqlalchemy/pool/base.py", line 1263, in _checkout
    fairy = _ConnectionRecord.checkout(pool)
  File "/home/frank/.local/lib/python3.10/site-packages/sqlalchemy/pool/base.py", line 712, in checkout
    rec = pool._do_get()
  File "/home/frank/.local/lib/python3.10/site-packages/sqlalchemy/pool/impl.py", line 179, in _do_get
    with util.safe_reraise():
  File "/home/frank/.local/lib/python3.10/site-packages/sqlalchemy/util/langhelpers.py", line 146, in __exit__
    raise exc_value.with_traceback(exc_tb)
  File "/home/frank/.local/lib/python3.10/site-packages/sqlalchemy/pool/impl.py", line 177, in _do_get
    return self._create_connection()
  File "/home/frank/.local/lib/python3.10/site-packages/sqlalchemy/pool/base.py", line 390, in _create_connection
    return _ConnectionRecord(self)
  File "/home/frank/.local/lib/python3.10/site-packages/sqlalchemy/pool/base.py", line 674, in __init__
    self.__connect()
  File "/home/frank/.local/lib/python3.10/site-packages/sqlalchemy/pool/base.py", line 900, in __connect
    with util.safe_reraise():
  File "/home/frank/.local/lib/python3.10/site-packages/sqlalchemy/util/langhelpers.py", line 146, in __exit__
    raise exc_value.with_traceback(exc_tb)
  File "/home/frank/.local/lib/python3.10/site-packages/sqlalchemy/pool/base.py", line 896, in __connect
    self.dbapi_connection = connection = pool._invoke_creator(self)
  File "/home/frank/.local/lib/python3.10/site-packages/sqlalchemy/engine/create.py", line 643, in connect
    return dialect.connect(*cargs, **cparams)
  File "/home/frank/.local/lib/python3.10/site-packages/sqlalchemy/engine/default.py", line 616, in connect
    return self.loaded_dbapi.connect(*cargs, **cparams)
  File "/home/frank/.local/lib/python3.10/site-packages/pymysql/connections.py", line 361, in __init__
    self.connect()
  File "/home/frank/.local/lib/python3.10/site-packages/pymysql/connections.py", line 669, in connect
    self._request_authentication()
  File "/home/frank/.local/lib/python3.10/site-packages/pymysql/connections.py", line 979, in _request_authentication
    auth_packet = _auth.caching_sha2_password_auth(self, auth_packet)
  File "/home/frank/.local/lib/python3.10/site-packages/pymysql/_auth.py", line 268, in caching_sha2_password_auth
    pkt = _roundtrip(conn, data)
  File "/home/frank/.local/lib/python3.10/site-packages/pymysql/_auth.py", line 121, in _roundtrip
    pkt = conn._read_packet()
  File "/home/frank/.local/lib/python3.10/site-packages/pymysql/connections.py", line 775, in _read_packet
    packet.raise_for_error()
  File "/home/frank/.local/lib/python3.10/site-packages/pymysql/protocol.py", line 219, in raise_for_error
    err.raise_mysql_exception(self._data)
  File "/home/frank/.local/lib/python3.10/site-packages/pymysql/err.py", line 150, in raise_mysql_exception
    raise errorclass(errno, errval)
sqlalchemy.exc.OperationalError: (pymysql.err.OperationalError) (1049, "Unknown database 'eazy_manage'")
(Background on this error at: https://sqlalche.me/e/20/e3q8)
2024-10-13 22:05:27,066 INFO Logging setup successfully: /home/frank/eazy_manage_backend/./app.py 43
2024-10-13 22:05:27,066 INFO DataBase set up successfully: /home/frank/eazy_manage_backend/./app.py 55
2024-10-13 22:05:27,193 WARNING database set up failed!: /home/frank/eazy_manage_backend/./app.py 68
Traceback (most recent call last):
  File "/home/frank/.local/lib/python3.10/site-packages/sqlalchemy/engine/base.py", line 145, in __init__
    self._dbapi_connection = engine.raw_connection()
  File "/home/frank/.local/lib/python3.10/site-packages/sqlalchemy/engine/base.py", line 3303, in raw_connection
    return self.pool.connect()
  File "/home/frank/.local/lib/python3.10/site-packages/sqlalchemy/pool/base.py", line 449, in connect
    return _ConnectionFairy._checkout(self)
  File "/home/frank/.local/lib/python3.10/site-packages/sqlalchemy/pool/base.py", line 1263, in _checkout
    fairy = _ConnectionRecord.checkout(pool)
  File "/home/frank/.local/lib/python3.10/site-packages/sqlalchemy/pool/base.py", line 712, in checkout
    rec = pool._do_get()
  File "/home/frank/.local/lib/python3.10/site-packages/sqlalchemy/pool/impl.py", line 179, in _do_get
    with util.safe_reraise():
  File "/home/frank/.local/lib/python3.10/site-packages/sqlalchemy/util/langhelpers.py", line 146, in __exit__
    raise exc_value.with_traceback(exc_tb)
  File "/home/frank/.local/lib/python3.10/site-packages/sqlalchemy/pool/impl.py", line 177, in _do_get
    return self._create_connection()
  File "/home/frank/.local/lib/python3.10/site-packages/sqlalchemy/pool/base.py", line 390, in _create_connection
    return _ConnectionRecord(self)
  File "/home/frank/.local/lib/python3.10/site-packages/sqlalchemy/pool/base.py", line 674, in __init__
    self.__connect()
  File "/home/frank/.local/lib/python3.10/site-packages/sqlalchemy/pool/base.py", line 900, in __connect
    with util.safe_reraise():
  File "/home/frank/.local/lib/python3.10/site-packages/sqlalchemy/util/langhelpers.py", line 146, in __exit__
    raise exc_value.with_traceback(exc_tb)
  File "/home/frank/.local/lib/python3.10/site-packages/sqlalchemy/pool/base.py", line 896, in __connect
    self.dbapi_connection = connection = pool._invoke_creator(self)
  File "/home/frank/.local/lib/python3.10/site-packages/sqlalchemy/engine/create.py", line 643, in connect
    return dialect.connect(*cargs, **cparams)
  File "/home/frank/.local/lib/python3.10/site-packages/sqlalchemy/engine/default.py", line 616, in connect
    return self.loaded_dbapi.connect(*cargs, **cparams)
  File "/home/frank/.local/lib/python3.10/site-packages/pymysql/connections.py", line 361, in __init__
    self.connect()
  File "/home/frank/.local/lib/python3.10/site-packages/pymysql/connections.py", line 669, in connect
    self._request_authentication()
  File "/home/frank/.local/lib/python3.10/site-packages/pymysql/connections.py", line 979, in _request_authentication
    auth_packet = _auth.caching_sha2_password_auth(self, auth_packet)
  File "/home/frank/.local/lib/python3.10/site-packages/pymysql/_auth.py", line 241, in caching_sha2_password_auth
    pkt = conn._read_packet()
  File "/home/frank/.local/lib/python3.10/site-packages/pymysql/connections.py", line 775, in _read_packet
    packet.raise_for_error()
  File "/home/frank/.local/lib/python3.10/site-packages/pymysql/protocol.py", line 219, in raise_for_error
    err.raise_mysql_exception(self._data)
  File "/home/frank/.local/lib/python3.10/site-packages/pymysql/err.py", line 150, in raise_mysql_exception
    raise errorclass(errno, errval)
pymysql.err.OperationalError: (1049, "Unknown database 'eazy_manage'")

The above exception was the direct cause of the following exception:

Traceback (most recent call last):
  File "/home/frank/eazy_manage_backend/./app.py", line 65, in create_app
    db.create_all()
  File "/home/frank/.local/lib/python3.10/site-packages/flask_sqlalchemy/extension.py", line 900, in create_all
    self._call_for_binds(bind_key, "create_all")
  File "/home/frank/.local/lib/python3.10/site-packages/flask_sqlalchemy/extension.py", line 881, in _call_for_binds
    getattr(metadata, op_name)(bind=engine)
  File "/home/frank/.local/lib/python3.10/site-packages/sqlalchemy/sql/schema.py", line 5825, in create_all
    bind._run_ddl_visitor(
  File "/home/frank/.local/lib/python3.10/site-packages/sqlalchemy/engine/base.py", line 3253, in _run_ddl_visitor
    with self.begin() as conn:
  File "/usr/lib/python3.10/contextlib.py", line 135, in __enter__
    return next(self.gen)
  File "/home/frank/.local/lib/python3.10/site-packages/sqlalchemy/engine/base.py", line 3243, in begin
    with self.connect() as conn:
  File "/home/frank/.local/lib/python3.10/site-packages/sqlalchemy/engine/base.py", line 3279, in connect
    return self._connection_cls(self)
  File "/home/frank/.local/lib/python3.10/site-packages/sqlalchemy/engine/base.py", line 147, in __init__
    Connection._handle_dbapi_exception_noconnection(
  File "/home/frank/.local/lib/python3.10/site-packages/sqlalchemy/engine/base.py", line 2443, in _handle_dbapi_exception_noconnection
    raise sqlalchemy_exception.with_traceback(exc_info[2]) from e
  File "/home/frank/.local/lib/python3.10/site-packages/sqlalchemy/engine/base.py", line 145, in __init__
    self._dbapi_connection = engine.raw_connection()
  File "/home/frank/.local/lib/python3.10/site-packages/sqlalchemy/engine/base.py", line 3303, in raw_connection
    return self.pool.connect()
  File "/home/frank/.local/lib/python3.10/site-packages/sqlalchemy/pool/base.py", line 449, in connect
    return _ConnectionFairy._checkout(self)
  File "/home/frank/.local/lib/python3.10/site-packages/sqlalchemy/pool/base.py", line 1263, in _checkout
    fairy = _ConnectionRecord.checkout(pool)
  File "/home/frank/.local/lib/python3.10/site-packages/sqlalchemy/pool/base.py", line 712, in checkout
    rec = pool._do_get()
  File "/home/frank/.local/lib/python3.10/site-packages/sqlalchemy/pool/impl.py", line 179, in _do_get
    with util.safe_reraise():
  File "/home/frank/.local/lib/python3.10/site-packages/sqlalchemy/util/langhelpers.py", line 146, in __exit__
    raise exc_value.with_traceback(exc_tb)
  File "/home/frank/.local/lib/python3.10/site-packages/sqlalchemy/pool/impl.py", line 177, in _do_get
    return self._create_connection()
  File "/home/frank/.local/lib/python3.10/site-packages/sqlalchemy/pool/base.py", line 390, in _create_connection
    return _ConnectionRecord(self)
  File "/home/frank/.local/lib/python3.10/site-packages/sqlalchemy/pool/base.py", line 674, in __init__
    self.__connect()
  File "/home/frank/.local/lib/python3.10/site-packages/sqlalchemy/pool/base.py", line 900, in __connect
    with util.safe_reraise():
  File "/home/frank/.local/lib/python3.10/site-packages/sqlalchemy/util/langhelpers.py", line 146, in __exit__
    raise exc_value.with_traceback(exc_tb)
  File "/home/frank/.local/lib/python3.10/site-packages/sqlalchemy/pool/base.py", line 896, in __connect
    self.dbapi_connection = connection = pool._invoke_creator(self)
  File "/home/frank/.local/lib/python3.10/site-packages/sqlalchemy/engine/create.py", line 643, in connect
    return dialect.connect(*cargs, **cparams)
  File "/home/frank/.local/lib/python3.10/site-packages/sqlalchemy/engine/default.py", line 616, in connect
    return self.loaded_dbapi.connect(*cargs, **cparams)
  File "/home/frank/.local/lib/python3.10/site-packages/pymysql/connections.py", line 361, in __init__
    self.connect()
  File "/home/frank/.local/lib/python3.10/site-packages/pymysql/connections.py", line 669, in connect
    self._request_authentication()
  File "/home/frank/.local/lib/python3.10/site-packages/pymysql/connections.py", line 979, in _request_authentication
    auth_packet = _auth.caching_sha2_password_auth(self, auth_packet)
  File "/home/frank/.local/lib/python3.10/site-packages/pymysql/_auth.py", line 241, in caching_sha2_password_auth
    pkt = conn._read_packet()
  File "/home/frank/.local/lib/python3.10/site-packages/pymysql/connections.py", line 775, in _read_packet
    packet.raise_for_error()
  File "/home/frank/.local/lib/python3.10/site-packages/pymysql/protocol.py", line 219, in raise_for_error
    err.raise_mysql_exception(self._data)
  File "/home/frank/.local/lib/python3.10/site-packages/pymysql/err.py", line 150, in raise_mysql_exception
    raise errorclass(errno, errval)
sqlalchemy.exc.OperationalError: (pymysql.err.OperationalError) (1049, "Unknown database 'eazy_manage'")
(Background on this error at: https://sqlalche.me/e/20/e3q8)
2024-10-13 22:07:41,264 INFO Logging setup successfully: /home/frank/eazy_manage_backend/./app.py 43
2024-10-13 22:07:41,264 INFO DataBase set up successfully: /home/frank/eazy_manage_backend/./app.py 55
2024-10-13 22:08:04,972 INFO databaase set up successfully: /home/frank/eazy_manage_backend/./app.py 66
2024-10-13 22:08:05,027 INFO Migrations set up successfully: /home/frank/eazy_manage_backend/./app.py 74
2024-10-13 22:08:05,031 INFO Blueprints registered successfully: /home/frank/eazy_manage_backend/./app.py 82
2024-10-13 22:08:05,031 INFO Mail service setup successfully: /home/frank/eazy_manage_backend/./app.py 95
2024-10-13 22:08:05,032 INFO App created successfully: /home/frank/eazy_manage_backend/./app.py 105
2024-10-13 22:08:06,982 INFO Logging setup successfully: /home/frank/eazy_manage_backend/./app.py 43
2024-10-13 22:08:06,982 INFO DataBase set up successfully: /home/frank/eazy_manage_backend/./app.py 55
2024-10-13 22:08:10,742 INFO databaase set up successfully: /home/frank/eazy_manage_backend/./app.py 66
2024-10-13 22:08:10,746 INFO Migrations set up successfully: /home/frank/eazy_manage_backend/./app.py 74
2024-10-13 22:08:10,752 INFO Blueprints registered successfully: /home/frank/eazy_manage_backend/./app.py 82
2024-10-13 22:08:10,752 INFO Mail service setup successfully: /home/frank/eazy_manage_backend/./app.py 95
2024-10-13 22:08:10,752 INFO App created successfully: /home/frank/eazy_manage_backend/./app.py 105
2024-10-13 22:09:51,198 INFO Logging setup successfully: /home/frank/eazy_manage_backend/./app.py 43
2024-10-13 22:09:51,199 INFO DataBase set up successfully: /home/frank/eazy_manage_backend/./app.py 55
2024-10-13 22:09:51,389 INFO database set up successfully: /home/frank/eazy_manage_backend/./app.py 60
2024-10-13 22:09:51,398 INFO Migrations set up successfully: /home/frank/eazy_manage_backend/./app.py 68
2024-10-13 22:09:51,407 INFO Blueprints registered successfully: /home/frank/eazy_manage_backend/./app.py 76
2024-10-13 22:09:51,407 INFO Mail service setup successfully: /home/frank/eazy_manage_backend/./app.py 89
2024-10-13 22:09:51,407 INFO App created successfully: /home/frank/eazy_manage_backend/./app.py 99
2024-10-13 22:10:00,041 INFO Logging setup successfully: /home/frank/eazy_manage_backend/./app.py 43
2024-10-13 22:10:00,041 INFO DataBase set up successfully: /home/frank/eazy_manage_backend/./app.py 55
2024-10-13 22:10:00,263 INFO database set up successfully: /home/frank/eazy_manage_backend/./app.py 60
2024-10-13 22:10:00,265 INFO Migrations set up successfully: /home/frank/eazy_manage_backend/./app.py 68
2024-10-13 22:10:00,270 INFO Blueprints registered successfully: /home/frank/eazy_manage_backend/./app.py 76
2024-10-13 22:10:00,270 INFO Mail service setup successfully: /home/frank/eazy_manage_backend/./app.py 89
2024-10-13 22:10:00,270 INFO App created successfully: /home/frank/eazy_manage_backend/./app.py 99
2024-10-13 22:10:01,301 INFO Logging setup successfully: /home/frank/eazy_manage_backend/./app.py 43
2024-10-13 22:10:01,301 INFO DataBase set up successfully: /home/frank/eazy_manage_backend/./app.py 55
2024-10-13 22:10:01,565 INFO database set up successfully: /home/frank/eazy_manage_backend/./app.py 60
2024-10-13 22:10:01,567 INFO Migrations set up successfully: /home/frank/eazy_manage_backend/./app.py 68
2024-10-13 22:10:01,571 INFO Blueprints registered successfully: /home/frank/eazy_manage_backend/./app.py 76
2024-10-13 22:10:01,571 INFO Mail service setup successfully: /home/frank/eazy_manage_backend/./app.py 89
2024-10-13 22:10:01,571 INFO App created successfully: /home/frank/eazy_manage_backend/./app.py 99
2024-10-13 22:11:05,039 ERROR Validation error on login: {'error': {'type': 'ValidationError', 'message': {'email': ['Not a valid email address.'], 'pwd': ['Unknown field.']}}}: /home/frank/eazy_manage_backend/api/v1/routes/auth.py 101
2024-10-13 22:11:07,345 ERROR Validation error on login: {'error': {'type': 'ValidationError', 'message': {'email': ['Not a valid email address.'], 'pwd': ['Unknown field.']}}}: /home/frank/eazy_manage_backend/api/v1/routes/auth.py 101
2024-10-13 22:11:08,076 ERROR Validation error on login: {'error': {'type': 'ValidationError', 'message': {'email': ['Not a valid email address.'], 'pwd': ['Unknown field.']}}}: /home/frank/eazy_manage_backend/api/v1/routes/auth.py 101
2024-10-13 22:11:15,763 ERROR Validation error on login: {'error': {'type': 'ValidationError', 'message': {'email': ['Not a valid email address.'], 'pwd': ['Unknown field.']}}}: /home/frank/eazy_manage_backend/api/v1/routes/auth.py 101
2024-10-13 22:11:24,341 ERROR Validation error on login: {'error': {'type': 'ValidationError', 'message': {'pwd': ['Unknown field.']}}}: /home/frank/eazy_manage_backend/api/v1/routes/auth.py 101
2024-10-14 20:56:55,035 INFO Logging setup successfully: /home/frank/eazy_manage_backend/./app.py 43
2024-10-14 20:56:55,046 INFO DataBase set up successfully: /home/frank/eazy_manage_backend/./app.py 55
2024-10-14 20:56:56,773 INFO database set up successfully: /home/frank/eazy_manage_backend/./app.py 60
2024-10-14 20:56:56,782 INFO Migrations set up successfully: /home/frank/eazy_manage_backend/./app.py 68
2024-10-14 20:56:56,796 INFO Blueprints registered successfully: /home/frank/eazy_manage_backend/./app.py 76
2024-10-14 20:56:56,796 INFO Mail service setup successfully: /home/frank/eazy_manage_backend/./app.py 89
2024-10-14 20:56:56,797 INFO App created successfully: /home/frank/eazy_manage_backend/./app.py 99
2024-10-14 20:56:59,463 INFO Logging setup successfully: /home/frank/eazy_manage_backend/./app.py 43
2024-10-14 20:56:59,463 INFO DataBase set up successfully: /home/frank/eazy_manage_backend/./app.py 55
2024-10-14 20:56:59,563 INFO database set up successfully: /home/frank/eazy_manage_backend/./app.py 60
2024-10-14 20:56:59,573 INFO Migrations set up successfully: /home/frank/eazy_manage_backend/./app.py 68
2024-10-14 20:56:59,590 INFO Blueprints registered successfully: /home/frank/eazy_manage_backend/./app.py 76
2024-10-14 20:56:59,591 INFO Mail service setup successfully: /home/frank/eazy_manage_backend/./app.py 89
2024-10-14 20:56:59,592 INFO App created successfully: /home/frank/eazy_manage_backend/./app.py 99
2024-10-14 21:05:50,948 INFO Logging setup successfully: /home/frank/eazy_manage_backend/./app.py 43
2024-10-14 21:05:50,948 INFO DataBase set up successfully: /home/frank/eazy_manage_backend/./app.py 55
2024-10-14 21:05:51,046 INFO database set up successfully: /home/frank/eazy_manage_backend/./app.py 60
2024-10-14 21:05:51,052 INFO Migrations set up successfully: /home/frank/eazy_manage_backend/./app.py 68
2024-10-14 21:05:51,060 INFO Blueprints registered successfully: /home/frank/eazy_manage_backend/./app.py 76
2024-10-14 21:05:51,061 INFO Mail service setup successfully: /home/frank/eazy_manage_backend/./app.py 89
2024-10-14 21:05:51,061 INFO App created successfully: /home/frank/eazy_manage_backend/./app.py 99
2024-10-14 21:05:54,020 INFO Logging setup successfully: /home/frank/eazy_manage_backend/./app.py 43
2024-10-14 21:05:54,022 INFO DataBase set up successfully: /home/frank/eazy_manage_backend/./app.py 55
2024-10-14 21:05:54,440 INFO database set up successfully: /home/frank/eazy_manage_backend/./app.py 60
2024-10-14 21:05:54,456 INFO Migrations set up successfully: /home/frank/eazy_manage_backend/./app.py 68
2024-10-14 21:05:54,489 INFO Blueprints registered successfully: /home/frank/eazy_manage_backend/./app.py 76
2024-10-14 21:05:54,490 INFO Mail service setup successfully: /home/frank/eazy_manage_backend/./app.py 89
2024-10-14 21:05:54,491 INFO App created successfully: /home/frank/eazy_manage_backend/./app.py 99
2024-10-14 23:34:16,637 INFO Logging setup successfully: /home/frank/eazy_manage_backend/app.py 43
2024-10-14 23:34:16,638 INFO DataBase set up successfully: /home/frank/eazy_manage_backend/app.py 55
2024-10-14 23:34:18,672 INFO database set up successfully: /home/frank/eazy_manage_backend/app.py 60
2024-10-14 23:34:18,682 INFO Migrations set up successfully: /home/frank/eazy_manage_backend/app.py 68
2024-10-14 23:34:18,696 INFO Blueprints registered successfully: /home/frank/eazy_manage_backend/app.py 76
2024-10-14 23:34:18,697 INFO Mail service setup successfully: /home/frank/eazy_manage_backend/app.py 89
2024-10-14 23:34:18,698 INFO App created successfully: /home/frank/eazy_manage_backend/app.py 99
2024-10-14 23:34:34,082 INFO Logging setup successfully: /home/frank/eazy_manage_backend/app.py 43
2024-10-14 23:34:34,082 INFO DataBase set up successfully: /home/frank/eazy_manage_backend/app.py 55
2024-10-14 23:34:34,199 INFO database set up successfully: /home/frank/eazy_manage_backend/app.py 60
2024-10-14 23:34:34,211 INFO Migrations set up successfully: /home/frank/eazy_manage_backend/app.py 68
2024-10-14 23:34:34,229 INFO Blueprints registered successfully: /home/frank/eazy_manage_backend/app.py 76
2024-10-14 23:34:34,230 INFO Mail service setup successfully: /home/frank/eazy_manage_backend/app.py 89
2024-10-14 23:34:34,230 INFO App created successfully: /home/frank/eazy_manage_backend/app.py 99
2024-10-14 23:35:17,426 INFO Logging setup successfully: /home/frank/eazy_manage_backend/app.py 43
2024-10-14 23:35:17,427 INFO DataBase set up successfully: /home/frank/eazy_manage_backend/app.py 55
2024-10-14 23:35:17,537 INFO database set up successfully: /home/frank/eazy_manage_backend/app.py 60
2024-10-14 23:35:17,544 INFO Migrations set up successfully: /home/frank/eazy_manage_backend/app.py 68
2024-10-14 23:35:17,555 INFO Blueprints registered successfully: /home/frank/eazy_manage_backend/app.py 76
2024-10-14 23:35:17,555 INFO Mail service setup successfully: /home/frank/eazy_manage_backend/app.py 89
2024-10-14 23:35:17,556 INFO App created successfully: /home/frank/eazy_manage_backend/app.py 99
2024-10-14 23:35:25,233 INFO Logging setup successfully: /home/frank/eazy_manage_backend/app.py 43
2024-10-14 23:35:25,234 INFO DataBase set up successfully: /home/frank/eazy_manage_backend/app.py 55
2024-10-14 23:35:25,355 INFO database set up successfully: /home/frank/eazy_manage_backend/app.py 60
2024-10-14 23:35:25,362 INFO Migrations set up successfully: /home/frank/eazy_manage_backend/app.py 68
2024-10-14 23:35:25,374 INFO Blueprints registered successfully: /home/frank/eazy_manage_backend/app.py 76
2024-10-14 23:35:25,375 INFO Mail service setup successfully: /home/frank/eazy_manage_backend/app.py 89
2024-10-14 23:35:25,376 INFO App created successfully: /home/frank/eazy_manage_backend/app.py 99
