2024-07-30 13:33:33,514 INFO Logging setup successfully: /home/frank/virtual_doctor_backend/./app.py 37
2024-07-30 13:33:33,515 INFO DataBase set up successfully: /home/frank/virtual_doctor_backend/./app.py 49
2024-07-30 13:33:33,643 INFO Migrations set up successfully: /home/frank/virtual_doctor_backend/./app.py 61
2024-07-30 13:33:33,673 INFO Blueprints registered successfully: /home/frank/virtual_doctor_backend/./app.py 69
2024-07-30 13:33:33,674 INFO Mail service setup successfully: /home/frank/virtual_doctor_backend/./app.py 82
2024-07-30 13:33:33,674 INFO App created successfully: /home/frank/virtual_doctor_backend/./app.py 92
2024-07-30 13:33:35,745 INFO Logging setup successfully: /home/frank/virtual_doctor_backend/./app.py 37
2024-07-30 13:33:35,745 INFO DataBase set up successfully: /home/frank/virtual_doctor_backend/./app.py 49
2024-07-30 13:33:35,865 INFO Migrations set up successfully: /home/frank/virtual_doctor_backend/./app.py 61
2024-07-30 13:33:35,895 INFO Blueprints registered successfully: /home/frank/virtual_doctor_backend/./app.py 69
2024-07-30 13:33:35,896 INFO Mail service setup successfully: /home/frank/virtual_doctor_backend/./app.py 82
2024-07-30 13:33:35,896 INFO App created successfully: /home/frank/virtual_doctor_backend/./app.py 92
2024-07-31 11:04:43,976 INFO Logging setup successfully: /home/frank/virtual_doctor_backend/./app.py 39
2024-07-31 11:04:43,993 INFO DataBase set up successfully: /home/frank/virtual_doctor_backend/./app.py 51
2024-07-31 11:04:53,967 INFO Migrations set up successfully: /home/frank/virtual_doctor_backend/./app.py 63
2024-07-31 11:04:53,973 CRITICAL Blueprints registration failed!: /home/frank/virtual_doctor_backend/./app.py 73
Traceback (most recent call last):
  File "/home/frank/virtual_doctor_backend/./app.py", line 70, in create_app
    register_routes(app)
  File "/home/frank/virtual_doctor_backend/api/__init__.py", line 16, in register_routes
    app.register_blueprint(auth_bp, url_prefix='/api/auth')
  File "/home/frank/.local/lib/python3.10/site-packages/flask/sansio/scaffold.py", line 47, in wrapper_func
    return f(self, *args, **kwargs)
  File "/home/frank/.local/lib/python3.10/site-packages/flask/sansio/app.py", line 595, in register_blueprint
    blueprint.register(self, options)
  File "/home/frank/.local/lib/python3.10/site-packages/flask/sansio/blueprints.py", line 335, in register
    deferred(state)
  File "/home/frank/.local/lib/python3.10/site-packages/flask/sansio/blueprints.py", line 434, in <lambda>
    lambda s: s.add_url_rule(
  File "/home/frank/.local/lib/python3.10/site-packages/flask/sansio/blueprints.py", line 110, in add_url_rule
    self.app.add_url_rule(
  File "/home/frank/.local/lib/python3.10/site-packages/flask/sansio/scaffold.py", line 47, in wrapper_func
    return f(self, *args, **kwargs)
  File "/home/frank/.local/lib/python3.10/site-packages/flask/sansio/app.py", line 653, in add_url_rule
    self.url_map.add(rule_obj)
  File "/home/frank/.local/lib/python3.10/site-packages/werkzeug/routing/map.py", line 169, in add
    rule.bind(self)
  File "/home/frank/.local/lib/python3.10/site-packages/werkzeug/routing/rules.py", line 563, in bind
    self.compile()
  File "/home/frank/.local/lib/python3.10/site-packages/werkzeug/routing/rules.py", line 708, in compile
    self._parts.extend(self._parse_rule(rule))
  File "/home/frank/.local/lib/python3.10/site-packages/werkzeug/routing/rules.py", line 600, in _parse_rule
    raise ValueError(f"malformed url rule: {rule!r}")
ValueError: malformed url rule: '/api/auth/login/<string: role>'
2024-07-31 11:07:27,473 INFO Logging setup successfully: /home/frank/virtual_doctor_backend/./app.py 39
2024-07-31 11:07:27,473 INFO DataBase set up successfully: /home/frank/virtual_doctor_backend/./app.py 51
2024-07-31 11:07:27,534 INFO Migrations set up successfully: /home/frank/virtual_doctor_backend/./app.py 63
2024-07-31 11:07:27,536 CRITICAL Blueprints registration failed!: /home/frank/virtual_doctor_backend/./app.py 73
Traceback (most recent call last):
  File "/home/frank/virtual_doctor_backend/./app.py", line 70, in create_app
    register_routes(app)
  File "/home/frank/virtual_doctor_backend/api/__init__.py", line 16, in register_routes
    app.register_blueprint(auth_bp, url_prefix='/api/auth')
  File "/home/frank/.local/lib/python3.10/site-packages/flask/sansio/scaffold.py", line 47, in wrapper_func
    return f(self, *args, **kwargs)
  File "/home/frank/.local/lib/python3.10/site-packages/flask/sansio/app.py", line 595, in register_blueprint
    blueprint.register(self, options)
  File "/home/frank/.local/lib/python3.10/site-packages/flask/sansio/blueprints.py", line 335, in register
    deferred(state)
  File "/home/frank/.local/lib/python3.10/site-packages/flask/sansio/blueprints.py", line 434, in <lambda>
    lambda s: s.add_url_rule(
  File "/home/frank/.local/lib/python3.10/site-packages/flask/sansio/blueprints.py", line 110, in add_url_rule
    self.app.add_url_rule(
  File "/home/frank/.local/lib/python3.10/site-packages/flask/sansio/scaffold.py", line 47, in wrapper_func
    return f(self, *args, **kwargs)
  File "/home/frank/.local/lib/python3.10/site-packages/flask/sansio/app.py", line 653, in add_url_rule
    self.url_map.add(rule_obj)
  File "/home/frank/.local/lib/python3.10/site-packages/werkzeug/routing/map.py", line 169, in add
    rule.bind(self)
  File "/home/frank/.local/lib/python3.10/site-packages/werkzeug/routing/rules.py", line 563, in bind
    self.compile()
  File "/home/frank/.local/lib/python3.10/site-packages/werkzeug/routing/rules.py", line 708, in compile
    self._parts.extend(self._parse_rule(rule))
  File "/home/frank/.local/lib/python3.10/site-packages/werkzeug/routing/rules.py", line 600, in _parse_rule
    raise ValueError(f"malformed url rule: {rule!r}")
ValueError: malformed url rule: '/api/auth/login/<string: role>'
2024-08-07 01:30:10,681 INFO Logging setup successfully: /home/frank/virtual_doctor_backend/./app.py 39
2024-08-07 01:30:10,689 INFO DataBase set up successfully: /home/frank/virtual_doctor_backend/./app.py 51
2024-08-07 01:30:12,233 INFO Migrations set up successfully: /home/frank/virtual_doctor_backend/./app.py 63
2024-08-07 01:30:12,282 CRITICAL Blueprints registration failed!: /home/frank/virtual_doctor_backend/./app.py 73
Traceback (most recent call last):
  File "/home/frank/virtual_doctor_backend/./app.py", line 70, in create_app
    register_routes(app)
  File "/home/frank/virtual_doctor_backend/api/__init__.py", line 16, in register_routes
    app.register_blueprint(auth_bp, url_prefix='/api/auth')
  File "/home/frank/.local/lib/python3.10/site-packages/flask/sansio/scaffold.py", line 47, in wrapper_func
    return f(self, *args, **kwargs)
  File "/home/frank/.local/lib/python3.10/site-packages/flask/sansio/app.py", line 595, in register_blueprint
    blueprint.register(self, options)
  File "/home/frank/.local/lib/python3.10/site-packages/flask/sansio/blueprints.py", line 335, in register
    deferred(state)
  File "/home/frank/.local/lib/python3.10/site-packages/flask/sansio/blueprints.py", line 434, in <lambda>
    lambda s: s.add_url_rule(
  File "/home/frank/.local/lib/python3.10/site-packages/flask/sansio/blueprints.py", line 110, in add_url_rule
    self.app.add_url_rule(
  File "/home/frank/.local/lib/python3.10/site-packages/flask/sansio/scaffold.py", line 47, in wrapper_func
    return f(self, *args, **kwargs)
  File "/home/frank/.local/lib/python3.10/site-packages/flask/sansio/app.py", line 653, in add_url_rule
    self.url_map.add(rule_obj)
  File "/home/frank/.local/lib/python3.10/site-packages/werkzeug/routing/map.py", line 169, in add
    rule.bind(self)
  File "/home/frank/.local/lib/python3.10/site-packages/werkzeug/routing/rules.py", line 563, in bind
    self.compile()
  File "/home/frank/.local/lib/python3.10/site-packages/werkzeug/routing/rules.py", line 708, in compile
    self._parts.extend(self._parse_rule(rule))
  File "/home/frank/.local/lib/python3.10/site-packages/werkzeug/routing/rules.py", line 600, in _parse_rule
    raise ValueError(f"malformed url rule: {rule!r}")
ValueError: malformed url rule: '/api/auth/login/<string: role>'
2024-08-07 01:30:30,619 INFO Logging setup successfully: /home/frank/virtual_doctor_backend/./app.py 39
2024-08-07 01:30:30,619 INFO DataBase set up successfully: /home/frank/virtual_doctor_backend/./app.py 51
2024-08-07 01:30:30,735 INFO Migrations set up successfully: /home/frank/virtual_doctor_backend/./app.py 63
2024-08-07 01:30:30,770 CRITICAL Blueprints registration failed!: /home/frank/virtual_doctor_backend/./app.py 73
Traceback (most recent call last):
  File "/home/frank/virtual_doctor_backend/./app.py", line 70, in create_app
    register_routes(app)
  File "/home/frank/virtual_doctor_backend/api/__init__.py", line 16, in register_routes
    app.register_blueprint(auth_bp, url_prefix='/api/auth')
  File "/home/frank/.local/lib/python3.10/site-packages/flask/sansio/scaffold.py", line 47, in wrapper_func
    return f(self, *args, **kwargs)
  File "/home/frank/.local/lib/python3.10/site-packages/flask/sansio/app.py", line 595, in register_blueprint
    blueprint.register(self, options)
  File "/home/frank/.local/lib/python3.10/site-packages/flask/sansio/blueprints.py", line 335, in register
    deferred(state)
  File "/home/frank/.local/lib/python3.10/site-packages/flask/sansio/blueprints.py", line 434, in <lambda>
    lambda s: s.add_url_rule(
  File "/home/frank/.local/lib/python3.10/site-packages/flask/sansio/blueprints.py", line 110, in add_url_rule
    self.app.add_url_rule(
  File "/home/frank/.local/lib/python3.10/site-packages/flask/sansio/scaffold.py", line 47, in wrapper_func
    return f(self, *args, **kwargs)
  File "/home/frank/.local/lib/python3.10/site-packages/flask/sansio/app.py", line 653, in add_url_rule
    self.url_map.add(rule_obj)
  File "/home/frank/.local/lib/python3.10/site-packages/werkzeug/routing/map.py", line 169, in add
    rule.bind(self)
  File "/home/frank/.local/lib/python3.10/site-packages/werkzeug/routing/rules.py", line 563, in bind
    self.compile()
  File "/home/frank/.local/lib/python3.10/site-packages/werkzeug/routing/rules.py", line 708, in compile
    self._parts.extend(self._parse_rule(rule))
  File "/home/frank/.local/lib/python3.10/site-packages/werkzeug/routing/rules.py", line 600, in _parse_rule
    raise ValueError(f"malformed url rule: {rule!r}")
ValueError: malformed url rule: '/api/auth/register/<string: role>'
2024-08-07 01:31:48,886 INFO Logging setup successfully: /home/frank/virtual_doctor_backend/./app.py 39
2024-08-07 01:31:48,886 INFO DataBase set up successfully: /home/frank/virtual_doctor_backend/./app.py 51
2024-08-07 01:31:48,995 INFO Migrations set up successfully: /home/frank/virtual_doctor_backend/./app.py 63
2024-08-07 01:31:49,039 CRITICAL Blueprints registration failed!: /home/frank/virtual_doctor_backend/./app.py 73
Traceback (most recent call last):
  File "/home/frank/virtual_doctor_backend/./app.py", line 70, in create_app
    register_routes(app)
  File "/home/frank/virtual_doctor_backend/api/__init__.py", line 16, in register_routes
    app.register_blueprint(auth_bp, url_prefix='/api/auth')
  File "/home/frank/.local/lib/python3.10/site-packages/flask/sansio/scaffold.py", line 47, in wrapper_func
    return f(self, *args, **kwargs)
  File "/home/frank/.local/lib/python3.10/site-packages/flask/sansio/app.py", line 595, in register_blueprint
    blueprint.register(self, options)
  File "/home/frank/.local/lib/python3.10/site-packages/flask/sansio/blueprints.py", line 335, in register
    deferred(state)
  File "/home/frank/.local/lib/python3.10/site-packages/flask/sansio/blueprints.py", line 434, in <lambda>
    lambda s: s.add_url_rule(
  File "/home/frank/.local/lib/python3.10/site-packages/flask/sansio/blueprints.py", line 110, in add_url_rule
    self.app.add_url_rule(
  File "/home/frank/.local/lib/python3.10/site-packages/flask/sansio/scaffold.py", line 47, in wrapper_func
    return f(self, *args, **kwargs)
  File "/home/frank/.local/lib/python3.10/site-packages/flask/sansio/app.py", line 653, in add_url_rule
    self.url_map.add(rule_obj)
  File "/home/frank/.local/lib/python3.10/site-packages/werkzeug/routing/map.py", line 169, in add
    rule.bind(self)
  File "/home/frank/.local/lib/python3.10/site-packages/werkzeug/routing/rules.py", line 563, in bind
    self.compile()
  File "/home/frank/.local/lib/python3.10/site-packages/werkzeug/routing/rules.py", line 708, in compile
    self._parts.extend(self._parse_rule(rule))
  File "/home/frank/.local/lib/python3.10/site-packages/werkzeug/routing/rules.py", line 600, in _parse_rule
    raise ValueError(f"malformed url rule: {rule!r}")
ValueError: malformed url rule: '/api/auth/register/<str: role>'
2024-08-07 01:34:56,648 INFO Logging setup successfully: /home/frank/virtual_doctor_backend/./app.py 39
2024-08-07 01:34:56,648 INFO DataBase set up successfully: /home/frank/virtual_doctor_backend/./app.py 51
2024-08-07 01:34:56,755 INFO Migrations set up successfully: /home/frank/virtual_doctor_backend/./app.py 63
2024-08-07 01:34:56,792 CRITICAL Blueprints registration failed!: /home/frank/virtual_doctor_backend/./app.py 73
Traceback (most recent call last):
  File "/home/frank/virtual_doctor_backend/./app.py", line 70, in create_app
    register_routes(app)
  File "/home/frank/virtual_doctor_backend/api/__init__.py", line 16, in register_routes
    app.register_blueprint(auth_bp, url_prefix='/api/auth')
  File "/home/frank/.local/lib/python3.10/site-packages/flask/sansio/scaffold.py", line 47, in wrapper_func
    return f(self, *args, **kwargs)
  File "/home/frank/.local/lib/python3.10/site-packages/flask/sansio/app.py", line 595, in register_blueprint
    blueprint.register(self, options)
  File "/home/frank/.local/lib/python3.10/site-packages/flask/sansio/blueprints.py", line 335, in register
    deferred(state)
  File "/home/frank/.local/lib/python3.10/site-packages/flask/sansio/blueprints.py", line 434, in <lambda>
    lambda s: s.add_url_rule(
  File "/home/frank/.local/lib/python3.10/site-packages/flask/sansio/blueprints.py", line 110, in add_url_rule
    self.app.add_url_rule(
  File "/home/frank/.local/lib/python3.10/site-packages/flask/sansio/scaffold.py", line 47, in wrapper_func
    return f(self, *args, **kwargs)
  File "/home/frank/.local/lib/python3.10/site-packages/flask/sansio/app.py", line 653, in add_url_rule
    self.url_map.add(rule_obj)
  File "/home/frank/.local/lib/python3.10/site-packages/werkzeug/routing/map.py", line 169, in add
    rule.bind(self)
  File "/home/frank/.local/lib/python3.10/site-packages/werkzeug/routing/rules.py", line 563, in bind
    self.compile()
  File "/home/frank/.local/lib/python3.10/site-packages/werkzeug/routing/rules.py", line 708, in compile
    self._parts.extend(self._parse_rule(rule))
  File "/home/frank/.local/lib/python3.10/site-packages/werkzeug/routing/rules.py", line 614, in _parse_rule
    convobj = self.get_converter(
  File "/home/frank/.local/lib/python3.10/site-packages/werkzeug/routing/rules.py", line 577, in get_converter
    raise LookupError(f"the converter {converter_name!r} does not exist")
LookupError: the converter 'str' does not exist
2024-08-07 01:35:25,643 INFO Logging setup successfully: /home/frank/virtual_doctor_backend/./app.py 39
2024-08-07 01:35:25,643 INFO DataBase set up successfully: /home/frank/virtual_doctor_backend/./app.py 51
2024-08-07 01:35:25,757 INFO Migrations set up successfully: /home/frank/virtual_doctor_backend/./app.py 63
2024-08-07 01:35:25,799 INFO Blueprints registered successfully: /home/frank/virtual_doctor_backend/./app.py 71
2024-08-07 01:35:25,799 INFO Mail service setup successfully: /home/frank/virtual_doctor_backend/./app.py 84
2024-08-07 01:35:25,800 INFO App created successfully: /home/frank/virtual_doctor_backend/./app.py 94
2024-08-07 01:35:28,520 INFO Logging setup successfully: /home/frank/virtual_doctor_backend/./app.py 39
2024-08-07 01:35:28,521 INFO DataBase set up successfully: /home/frank/virtual_doctor_backend/./app.py 51
2024-08-07 01:35:28,680 INFO Migrations set up successfully: /home/frank/virtual_doctor_backend/./app.py 63
2024-08-07 01:35:28,725 INFO Blueprints registered successfully: /home/frank/virtual_doctor_backend/./app.py 71
2024-08-07 01:35:28,725 INFO Mail service setup successfully: /home/frank/virtual_doctor_backend/./app.py 84
2024-08-07 01:35:28,726 INFO App created successfully: /home/frank/virtual_doctor_backend/./app.py 94
2024-08-08 17:04:02,938 INFO Logging setup successfully: /home/frank/virtual_doctor_backend/./app.py 49
2024-08-08 17:04:02,983 INFO DataBase set up successfully: /home/frank/virtual_doctor_backend/./app.py 61
2024-08-08 17:04:03,209 INFO Migrations set up successfully: /home/frank/virtual_doctor_backend/./app.py 73
2024-08-08 17:04:03,251 INFO Blueprints registered successfully: /home/frank/virtual_doctor_backend/./app.py 81
2024-08-08 17:04:03,251 INFO Mail service setup successfully: /home/frank/virtual_doctor_backend/./app.py 94
2024-08-08 17:04:03,252 INFO App created successfully: /home/frank/virtual_doctor_backend/./app.py 104
2024-08-08 17:04:06,298 INFO Logging setup successfully: /home/frank/virtual_doctor_backend/./app.py 49
2024-08-08 17:04:06,299 INFO DataBase set up successfully: /home/frank/virtual_doctor_backend/./app.py 61
2024-08-08 17:04:06,460 INFO Migrations set up successfully: /home/frank/virtual_doctor_backend/./app.py 73
2024-08-08 17:04:06,496 INFO Blueprints registered successfully: /home/frank/virtual_doctor_backend/./app.py 81
2024-08-08 17:04:06,497 INFO Mail service setup successfully: /home/frank/virtual_doctor_backend/./app.py 94
2024-08-08 17:04:06,497 INFO App created successfully: /home/frank/virtual_doctor_backend/./app.py 104
2024-08-08 17:05:50,069 INFO Logging setup successfully: /home/frank/virtual_doctor_backend/./app.py 49
2024-08-08 17:05:50,069 INFO DataBase set up successfully: /home/frank/virtual_doctor_backend/./app.py 61
2024-08-08 17:05:50,224 INFO Migrations set up successfully: /home/frank/virtual_doctor_backend/./app.py 73
2024-08-08 17:05:50,271 INFO Blueprints registered successfully: /home/frank/virtual_doctor_backend/./app.py 81
2024-08-08 17:05:50,271 INFO Mail service setup successfully: /home/frank/virtual_doctor_backend/./app.py 94
2024-08-08 17:05:50,272 INFO App created successfully: /home/frank/virtual_doctor_backend/./app.py 104
2024-08-08 17:10:21,739 INFO Logging setup successfully: /home/frank/virtual_doctor_backend/./app.py 32
2024-08-08 17:10:21,739 CRITICAL Uploads directory not set up: /home/frank/virtual_doctor_backend/./app.py 52
Traceback (most recent call last):
  File "/home/frank/virtual_doctor_backend/./app.py", line 41, in create_app
    pharmacy_dir = os.path.join(app.config('UPLOAD_FOLDER'), 'pharmacy')
TypeError: 'Config' object is not callable
2024-08-08 17:12:11,959 INFO Logging setup successfully: /home/frank/virtual_doctor_backend/./app.py 32
2024-08-08 17:12:11,960 CRITICAL Uploads directory not set up: /home/frank/virtual_doctor_backend/./app.py 52
Traceback (most recent call last):
  File "/home/frank/virtual_doctor_backend/./app.py", line 44, in create_app
    prescription_dir = os.path.join(app.config('UPLOAD_FOLDER'), 'prescriptions')
TypeError: 'Config' object is not callable
2024-08-08 17:13:47,742 INFO Logging setup successfully: /home/frank/virtual_doctor_backend/./app.py 32
2024-08-08 17:13:47,763 INFO Uploads directory set up successfully: /home/frank/virtual_doctor_backend/./app.py 50
NoneType: None
2024-08-08 17:13:47,764 INFO DataBase set up successfully: /home/frank/virtual_doctor_backend/./app.py 62
2024-08-08 17:13:47,900 INFO Migrations set up successfully: /home/frank/virtual_doctor_backend/./app.py 74
2024-08-08 17:13:47,936 INFO Blueprints registered successfully: /home/frank/virtual_doctor_backend/./app.py 82
2024-08-08 17:13:47,937 INFO Mail service setup successfully: /home/frank/virtual_doctor_backend/./app.py 95
2024-08-08 17:13:47,937 INFO App created successfully: /home/frank/virtual_doctor_backend/./app.py 105
2024-08-08 17:13:49,940 INFO Logging setup successfully: /home/frank/virtual_doctor_backend/./app.py 32
2024-08-08 17:13:49,940 INFO Uploads directory set up successfully: /home/frank/virtual_doctor_backend/./app.py 50
NoneType: None
2024-08-08 17:13:49,940 INFO DataBase set up successfully: /home/frank/virtual_doctor_backend/./app.py 62
2024-08-08 17:13:50,062 INFO Migrations set up successfully: /home/frank/virtual_doctor_backend/./app.py 74
2024-08-08 17:13:50,092 INFO Blueprints registered successfully: /home/frank/virtual_doctor_backend/./app.py 82
2024-08-08 17:13:50,092 INFO Mail service setup successfully: /home/frank/virtual_doctor_backend/./app.py 95
2024-08-08 17:13:50,092 INFO App created successfully: /home/frank/virtual_doctor_backend/./app.py 105
2024-08-08 17:15:32,101 INFO Logging setup successfully: /home/frank/virtual_doctor_backend/app.py 32
2024-08-08 17:15:32,102 INFO Uploads directory set up successfully: /home/frank/virtual_doctor_backend/app.py 50
NoneType: None
2024-08-08 17:15:32,102 INFO DataBase set up successfully: /home/frank/virtual_doctor_backend/app.py 62
2024-08-08 17:15:32,228 INFO Migrations set up successfully: /home/frank/virtual_doctor_backend/app.py 74
2024-08-08 17:15:32,321 INFO Blueprints registered successfully: /home/frank/virtual_doctor_backend/app.py 82
2024-08-08 17:15:32,322 INFO Mail service setup successfully: /home/frank/virtual_doctor_backend/app.py 95
2024-08-08 17:15:32,323 INFO App created successfully: /home/frank/virtual_doctor_backend/app.py 105
2024-08-08 17:17:11,269 INFO Logging setup successfully: /home/frank/virtual_doctor_backend/app.py 32
2024-08-08 17:17:11,270 INFO Uploads directory set up successfully: /home/frank/virtual_doctor_backend/app.py 50
NoneType: None
2024-08-08 17:17:11,271 INFO DataBase set up successfully: /home/frank/virtual_doctor_backend/app.py 62
2024-08-08 17:17:11,500 INFO Migrations set up successfully: /home/frank/virtual_doctor_backend/app.py 74
2024-08-08 17:17:11,650 INFO Blueprints registered successfully: /home/frank/virtual_doctor_backend/app.py 82
2024-08-08 17:17:11,651 INFO Mail service setup successfully: /home/frank/virtual_doctor_backend/app.py 95
2024-08-08 17:17:11,651 INFO App created successfully: /home/frank/virtual_doctor_backend/app.py 105
2024-08-08 17:17:18,057 INFO Logging setup successfully: /home/frank/virtual_doctor_backend/./app.py 32
2024-08-08 17:17:18,058 INFO Uploads directory set up successfully: /home/frank/virtual_doctor_backend/./app.py 50
NoneType: None
2024-08-08 17:17:18,059 INFO DataBase set up successfully: /home/frank/virtual_doctor_backend/./app.py 62
2024-08-08 17:17:18,242 INFO Migrations set up successfully: /home/frank/virtual_doctor_backend/./app.py 74
2024-08-08 17:17:18,281 INFO Blueprints registered successfully: /home/frank/virtual_doctor_backend/./app.py 82
2024-08-08 17:17:18,281 INFO Mail service setup successfully: /home/frank/virtual_doctor_backend/./app.py 95
2024-08-08 17:17:18,282 INFO App created successfully: /home/frank/virtual_doctor_backend/./app.py 105
2024-08-08 17:18:39,334 INFO Logging setup successfully: /home/frank/virtual_doctor_backend/app.py 32
2024-08-08 17:18:39,334 INFO Uploads directory set up successfully: /home/frank/virtual_doctor_backend/app.py 50
NoneType: None
2024-08-08 17:18:39,335 INFO DataBase set up successfully: /home/frank/virtual_doctor_backend/app.py 62
2024-08-08 17:18:39,448 INFO Migrations set up successfully: /home/frank/virtual_doctor_backend/app.py 74
2024-08-08 17:18:39,538 INFO Blueprints registered successfully: /home/frank/virtual_doctor_backend/app.py 82
2024-08-08 17:18:39,538 INFO Mail service setup successfully: /home/frank/virtual_doctor_backend/app.py 95
2024-08-08 17:18:39,539 INFO App created successfully: /home/frank/virtual_doctor_backend/app.py 105
2024-08-08 17:19:05,796 INFO Logging setup successfully: /home/frank/virtual_doctor_backend/app.py 32
2024-08-08 17:19:05,796 INFO Uploads directory set up successfully: /home/frank/virtual_doctor_backend/app.py 50
NoneType: None
2024-08-08 17:19:05,797 INFO DataBase set up successfully: /home/frank/virtual_doctor_backend/app.py 62
2024-08-08 17:19:05,918 INFO Migrations set up successfully: /home/frank/virtual_doctor_backend/app.py 74
2024-08-08 17:19:06,009 INFO Blueprints registered successfully: /home/frank/virtual_doctor_backend/app.py 82
2024-08-08 17:19:06,009 INFO Mail service setup successfully: /home/frank/virtual_doctor_backend/app.py 95
2024-08-08 17:19:06,010 INFO App created successfully: /home/frank/virtual_doctor_backend/app.py 105
2024-08-08 17:21:34,260 INFO Logging setup successfully: /home/frank/virtual_doctor_backend/./app.py 32
2024-08-08 17:21:34,260 INFO Uploads directory set up successfully: /home/frank/virtual_doctor_backend/./app.py 50
NoneType: None
2024-08-08 17:21:34,261 INFO DataBase set up successfully: /home/frank/virtual_doctor_backend/./app.py 62
2024-08-08 17:21:34,320 WARNING Migration set up failed!: /home/frank/virtual_doctor_backend/./app.py 76
Traceback (most recent call last):
  File "/home/frank/.local/lib/python3.10/site-packages/sqlalchemy/engine/base.py", line 145, in __init__
    self._dbapi_connection = engine.raw_connection()
  File "/home/frank/.local/lib/python3.10/site-packages/sqlalchemy/engine/base.py", line 3303, in raw_connection
    return self.pool.connect()
  File "/home/frank/.local/lib/python3.10/site-packages/sqlalchemy/pool/base.py", line 449, in connect
    return _ConnectionFairy._checkout(self)
  File "/home/frank/.local/lib/python3.10/site-packages/sqlalchemy/pool/base.py", line 1263, in _checkout
    fairy = _ConnectionRecord.checkout(pool)
  File "/home/frank/.local/lib/python3.10/site-packages/sqlalchemy/pool/base.py", line 712, in checkout
    rec = pool._do_get()
  File "/home/frank/.local/lib/python3.10/site-packages/sqlalchemy/pool/impl.py", line 179, in _do_get
    with util.safe_reraise():
  File "/home/frank/.local/lib/python3.10/site-packages/sqlalchemy/util/langhelpers.py", line 146, in __exit__
    raise exc_value.with_traceback(exc_tb)
  File "/home/frank/.local/lib/python3.10/site-packages/sqlalchemy/pool/impl.py", line 177, in _do_get
    return self._create_connection()
  File "/home/frank/.local/lib/python3.10/site-packages/sqlalchemy/pool/base.py", line 390, in _create_connection
    return _ConnectionRecord(self)
  File "/home/frank/.local/lib/python3.10/site-packages/sqlalchemy/pool/base.py", line 674, in __init__
    self.__connect()
  File "/home/frank/.local/lib/python3.10/site-packages/sqlalchemy/pool/base.py", line 900, in __connect
    with util.safe_reraise():
  File "/home/frank/.local/lib/python3.10/site-packages/sqlalchemy/util/langhelpers.py", line 146, in __exit__
    raise exc_value.with_traceback(exc_tb)
  File "/home/frank/.local/lib/python3.10/site-packages/sqlalchemy/pool/base.py", line 896, in __connect
    self.dbapi_connection = connection = pool._invoke_creator(self)
  File "/home/frank/.local/lib/python3.10/site-packages/sqlalchemy/engine/create.py", line 643, in connect
    return dialect.connect(*cargs, **cparams)
  File "/home/frank/.local/lib/python3.10/site-packages/sqlalchemy/engine/default.py", line 616, in connect
    return self.loaded_dbapi.connect(*cargs, **cparams)
  File "/home/frank/.local/lib/python3.10/site-packages/pymysql/connections.py", line 361, in __init__
    self.connect()
  File "/home/frank/.local/lib/python3.10/site-packages/pymysql/connections.py", line 669, in connect
    self._request_authentication()
  File "/home/frank/.local/lib/python3.10/site-packages/pymysql/connections.py", line 979, in _request_authentication
    auth_packet = _auth.caching_sha2_password_auth(self, auth_packet)
  File "/home/frank/.local/lib/python3.10/site-packages/pymysql/_auth.py", line 241, in caching_sha2_password_auth
    pkt = conn._read_packet()
  File "/home/frank/.local/lib/python3.10/site-packages/pymysql/connections.py", line 775, in _read_packet
    packet.raise_for_error()
  File "/home/frank/.local/lib/python3.10/site-packages/pymysql/protocol.py", line 219, in raise_for_error
    err.raise_mysql_exception(self._data)
  File "/home/frank/.local/lib/python3.10/site-packages/pymysql/err.py", line 150, in raise_mysql_exception
    raise errorclass(errno, errval)
pymysql.err.OperationalError: (1049, "Unknown database 'virtual_doctor'")

The above exception was the direct cause of the following exception:

Traceback (most recent call last):
  File "/home/frank/virtual_doctor_backend/./app.py", line 72, in create_app
    db.create_all()
  File "/home/frank/.local/lib/python3.10/site-packages/flask_sqlalchemy/extension.py", line 900, in create_all
    self._call_for_binds(bind_key, "create_all")
  File "/home/frank/.local/lib/python3.10/site-packages/flask_sqlalchemy/extension.py", line 881, in _call_for_binds
    getattr(metadata, op_name)(bind=engine)
  File "/home/frank/.local/lib/python3.10/site-packages/sqlalchemy/sql/schema.py", line 5825, in create_all
    bind._run_ddl_visitor(
  File "/home/frank/.local/lib/python3.10/site-packages/sqlalchemy/engine/base.py", line 3253, in _run_ddl_visitor
    with self.begin() as conn:
  File "/usr/lib/python3.10/contextlib.py", line 135, in __enter__
    return next(self.gen)
  File "/home/frank/.local/lib/python3.10/site-packages/sqlalchemy/engine/base.py", line 3243, in begin
    with self.connect() as conn:
  File "/home/frank/.local/lib/python3.10/site-packages/sqlalchemy/engine/base.py", line 3279, in connect
    return self._connection_cls(self)
  File "/home/frank/.local/lib/python3.10/site-packages/sqlalchemy/engine/base.py", line 147, in __init__
    Connection._handle_dbapi_exception_noconnection(
  File "/home/frank/.local/lib/python3.10/site-packages/sqlalchemy/engine/base.py", line 2443, in _handle_dbapi_exception_noconnection
    raise sqlalchemy_exception.with_traceback(exc_info[2]) from e
  File "/home/frank/.local/lib/python3.10/site-packages/sqlalchemy/engine/base.py", line 145, in __init__
    self._dbapi_connection = engine.raw_connection()
  File "/home/frank/.local/lib/python3.10/site-packages/sqlalchemy/engine/base.py", line 3303, in raw_connection
    return self.pool.connect()
  File "/home/frank/.local/lib/python3.10/site-packages/sqlalchemy/pool/base.py", line 449, in connect
    return _ConnectionFairy._checkout(self)
  File "/home/frank/.local/lib/python3.10/site-packages/sqlalchemy/pool/base.py", line 1263, in _checkout
    fairy = _ConnectionRecord.checkout(pool)
  File "/home/frank/.local/lib/python3.10/site-packages/sqlalchemy/pool/base.py", line 712, in checkout
    rec = pool._do_get()
  File "/home/frank/.local/lib/python3.10/site-packages/sqlalchemy/pool/impl.py", line 179, in _do_get
    with util.safe_reraise():
  File "/home/frank/.local/lib/python3.10/site-packages/sqlalchemy/util/langhelpers.py", line 146, in __exit__
    raise exc_value.with_traceback(exc_tb)
  File "/home/frank/.local/lib/python3.10/site-packages/sqlalchemy/pool/impl.py", line 177, in _do_get
    return self._create_connection()
  File "/home/frank/.local/lib/python3.10/site-packages/sqlalchemy/pool/base.py", line 390, in _create_connection
    return _ConnectionRecord(self)
  File "/home/frank/.local/lib/python3.10/site-packages/sqlalchemy/pool/base.py", line 674, in __init__
    self.__connect()
  File "/home/frank/.local/lib/python3.10/site-packages/sqlalchemy/pool/base.py", line 900, in __connect
    with util.safe_reraise():
  File "/home/frank/.local/lib/python3.10/site-packages/sqlalchemy/util/langhelpers.py", line 146, in __exit__
    raise exc_value.with_traceback(exc_tb)
  File "/home/frank/.local/lib/python3.10/site-packages/sqlalchemy/pool/base.py", line 896, in __connect
    self.dbapi_connection = connection = pool._invoke_creator(self)
  File "/home/frank/.local/lib/python3.10/site-packages/sqlalchemy/engine/create.py", line 643, in connect
    return dialect.connect(*cargs, **cparams)
  File "/home/frank/.local/lib/python3.10/site-packages/sqlalchemy/engine/default.py", line 616, in connect
    return self.loaded_dbapi.connect(*cargs, **cparams)
  File "/home/frank/.local/lib/python3.10/site-packages/pymysql/connections.py", line 361, in __init__
    self.connect()
  File "/home/frank/.local/lib/python3.10/site-packages/pymysql/connections.py", line 669, in connect
    self._request_authentication()
  File "/home/frank/.local/lib/python3.10/site-packages/pymysql/connections.py", line 979, in _request_authentication
    auth_packet = _auth.caching_sha2_password_auth(self, auth_packet)
  File "/home/frank/.local/lib/python3.10/site-packages/pymysql/_auth.py", line 241, in caching_sha2_password_auth
    pkt = conn._read_packet()
  File "/home/frank/.local/lib/python3.10/site-packages/pymysql/connections.py", line 775, in _read_packet
    packet.raise_for_error()
  File "/home/frank/.local/lib/python3.10/site-packages/pymysql/protocol.py", line 219, in raise_for_error
    err.raise_mysql_exception(self._data)
  File "/home/frank/.local/lib/python3.10/site-packages/pymysql/err.py", line 150, in raise_mysql_exception
    raise errorclass(errno, errval)
sqlalchemy.exc.OperationalError: (pymysql.err.OperationalError) (1049, "Unknown database 'virtual_doctor'")
(Background on this error at: https://sqlalche.me/e/20/e3q8)
2024-08-08 17:24:54,043 INFO Logging setup successfully: /home/frank/virtual_doctor_backend/app.py 32
2024-08-08 17:24:54,044 INFO Uploads directory set up successfully: /home/frank/virtual_doctor_backend/app.py 50
NoneType: None
2024-08-08 17:24:54,044 INFO DataBase set up successfully: /home/frank/virtual_doctor_backend/app.py 62
2024-08-08 17:25:28,123 WARNING Migration set up failed!: /home/frank/virtual_doctor_backend/app.py 76
Traceback (most recent call last):
  File "/home/frank/virtual_doctor_backend/app.py", line 72, in create_app
    db.create_all()
  File "/home/frank/.local/lib/python3.10/site-packages/flask_sqlalchemy/extension.py", line 900, in create_all
    self._call_for_binds(bind_key, "create_all")
  File "/home/frank/.local/lib/python3.10/site-packages/flask_sqlalchemy/extension.py", line 881, in _call_for_binds
    getattr(metadata, op_name)(bind=engine)
  File "/home/frank/.local/lib/python3.10/site-packages/sqlalchemy/sql/schema.py", line 5825, in create_all
    bind._run_ddl_visitor(
  File "/home/frank/.local/lib/python3.10/site-packages/sqlalchemy/engine/base.py", line 3254, in _run_ddl_visitor
    conn._run_ddl_visitor(visitorcallable, element, **kwargs)
  File "/home/frank/.local/lib/python3.10/site-packages/sqlalchemy/engine/base.py", line 2460, in _run_ddl_visitor
    visitorcallable(self.dialect, self, **kwargs).traverse_single(element)
  File "/home/frank/.local/lib/python3.10/site-packages/sqlalchemy/sql/visitors.py", line 664, in traverse_single
    return meth(obj, **kw)
  File "/home/frank/.local/lib/python3.10/site-packages/sqlalchemy/sql/ddl.py", line 918, in visit_metadata
    self.traverse_single(
  File "/home/frank/.local/lib/python3.10/site-packages/sqlalchemy/sql/visitors.py", line 664, in traverse_single
    return meth(obj, **kw)
  File "/home/frank/.local/lib/python3.10/site-packages/sqlalchemy/sql/ddl.py", line 956, in visit_table
    )._invoke_with(self.connection)
  File "/home/frank/.local/lib/python3.10/site-packages/sqlalchemy/sql/ddl.py", line 314, in _invoke_with
    return bind.execute(self)
  File "/home/frank/.local/lib/python3.10/site-packages/sqlalchemy/engine/base.py", line 1421, in execute
    return meth(
  File "/home/frank/.local/lib/python3.10/site-packages/sqlalchemy/sql/ddl.py", line 180, in _execute_on_connection
    return connection._execute_ddl(
  File "/home/frank/.local/lib/python3.10/site-packages/sqlalchemy/engine/base.py", line 1532, in _execute_ddl
    ret = self._execute_context(
  File "/home/frank/.local/lib/python3.10/site-packages/sqlalchemy/engine/base.py", line 1849, in _execute_context
    return self._exec_single_context(
  File "/home/frank/.local/lib/python3.10/site-packages/sqlalchemy/engine/base.py", line 1989, in _exec_single_context
    self._handle_dbapi_exception(
  File "/home/frank/.local/lib/python3.10/site-packages/sqlalchemy/engine/base.py", line 2359, in _handle_dbapi_exception
    raise exc_info[1].with_traceback(exc_info[2])
  File "/home/frank/.local/lib/python3.10/site-packages/sqlalchemy/engine/base.py", line 1970, in _exec_single_context
    self.dialect.do_execute(
  File "/home/frank/.local/lib/python3.10/site-packages/sqlalchemy/engine/default.py", line 924, in do_execute
    cursor.execute(statement, parameters)
  File "/home/frank/.local/lib/python3.10/site-packages/pymysql/cursors.py", line 153, in execute
    result = self._query(query)
  File "/home/frank/.local/lib/python3.10/site-packages/pymysql/cursors.py", line 322, in _query
    conn.query(q)
  File "/home/frank/.local/lib/python3.10/site-packages/pymysql/connections.py", line 563, in query
    self._affected_rows = self._read_query_result(unbuffered=unbuffered)
  File "/home/frank/.local/lib/python3.10/site-packages/pymysql/connections.py", line 825, in _read_query_result
    result.read()
  File "/home/frank/.local/lib/python3.10/site-packages/pymysql/connections.py", line 1199, in read
    first_packet = self.connection._read_packet()
  File "/home/frank/.local/lib/python3.10/site-packages/pymysql/connections.py", line 744, in _read_packet
    packet_header = self._read_bytes(4)
  File "/home/frank/.local/lib/python3.10/site-packages/pymysql/connections.py", line 782, in _read_bytes
    data = self._rfile.read(num_bytes)
  File "/usr/lib/python3.10/socket.py", line 705, in readinto
    return self._sock.recv_into(b)
KeyboardInterrupt
2024-08-08 17:27:44,617 INFO Logging setup successfully: /home/frank/virtual_doctor_backend/app.py 32
2024-08-08 17:27:44,617 INFO Uploads directory set up successfully: /home/frank/virtual_doctor_backend/app.py 50
NoneType: None
2024-08-08 17:27:44,618 INFO DataBase set up successfully: /home/frank/virtual_doctor_backend/app.py 62
2024-08-08 17:28:34,570 INFO Migrations set up successfully: /home/frank/virtual_doctor_backend/app.py 74
2024-08-08 17:28:34,738 INFO Blueprints registered successfully: /home/frank/virtual_doctor_backend/app.py 82
2024-08-08 17:28:34,740 INFO Mail service setup successfully: /home/frank/virtual_doctor_backend/app.py 95
2024-08-08 17:28:34,740 INFO App created successfully: /home/frank/virtual_doctor_backend/app.py 105
2024-08-08 17:28:43,583 INFO Logging setup successfully: /home/frank/virtual_doctor_backend/app.py 32
2024-08-08 17:28:43,583 INFO Uploads directory set up successfully: /home/frank/virtual_doctor_backend/app.py 50
NoneType: None
2024-08-08 17:28:43,584 INFO DataBase set up successfully: /home/frank/virtual_doctor_backend/app.py 62
2024-08-08 17:28:43,805 INFO Migrations set up successfully: /home/frank/virtual_doctor_backend/app.py 74
2024-08-08 17:28:43,964 INFO Blueprints registered successfully: /home/frank/virtual_doctor_backend/app.py 82
2024-08-08 17:28:43,964 INFO Mail service setup successfully: /home/frank/virtual_doctor_backend/app.py 95
2024-08-08 17:28:43,965 INFO App created successfully: /home/frank/virtual_doctor_backend/app.py 105
2024-08-08 17:30:08,476 INFO Logging setup successfully: /home/frank/virtual_doctor_backend/./app.py 32
2024-08-08 17:30:08,476 INFO Uploads directory set up successfully: /home/frank/virtual_doctor_backend/./app.py 50
NoneType: None
2024-08-08 17:30:08,477 INFO DataBase set up successfully: /home/frank/virtual_doctor_backend/./app.py 62
2024-08-08 17:30:08,594 INFO Migrations set up successfully: /home/frank/virtual_doctor_backend/./app.py 74
2024-08-08 17:30:08,625 INFO Blueprints registered successfully: /home/frank/virtual_doctor_backend/./app.py 82
2024-08-08 17:30:08,626 INFO Mail service setup successfully: /home/frank/virtual_doctor_backend/./app.py 95
2024-08-08 17:30:08,626 INFO App created successfully: /home/frank/virtual_doctor_backend/./app.py 105
2024-08-08 17:30:11,149 INFO Logging setup successfully: /home/frank/virtual_doctor_backend/./app.py 32
2024-08-08 17:30:11,150 INFO Uploads directory set up successfully: /home/frank/virtual_doctor_backend/./app.py 50
NoneType: None
2024-08-08 17:30:11,150 INFO DataBase set up successfully: /home/frank/virtual_doctor_backend/./app.py 62
2024-08-08 17:30:11,319 INFO Migrations set up successfully: /home/frank/virtual_doctor_backend/./app.py 74
2024-08-08 17:30:11,359 INFO Blueprints registered successfully: /home/frank/virtual_doctor_backend/./app.py 82
2024-08-08 17:30:11,360 INFO Mail service setup successfully: /home/frank/virtual_doctor_backend/./app.py 95
2024-08-08 17:30:11,360 INFO App created successfully: /home/frank/virtual_doctor_backend/./app.py 105
2024-08-08 20:39:44,511 INFO Logging setup successfully: /home/frank/virtual_doctor_backend/./app.py 32
2024-08-08 20:39:44,512 INFO Uploads directory set up successfully: /home/frank/virtual_doctor_backend/./app.py 50
NoneType: None
2024-08-08 20:39:44,512 INFO DataBase set up successfully: /home/frank/virtual_doctor_backend/./app.py 62
2024-08-08 20:39:44,793 INFO Migrations set up successfully: /home/frank/virtual_doctor_backend/./app.py 74
2024-08-08 20:39:44,878 INFO Blueprints registered successfully: /home/frank/virtual_doctor_backend/./app.py 82
2024-08-08 20:39:44,879 INFO Mail service setup successfully: /home/frank/virtual_doctor_backend/./app.py 95
2024-08-08 20:39:44,879 INFO App created successfully: /home/frank/virtual_doctor_backend/./app.py 105
2024-08-08 20:39:59,999 INFO Logging setup successfully: /home/frank/virtual_doctor_backend/app.py 32
2024-08-08 20:40:00,001 INFO Uploads directory set up successfully: /home/frank/virtual_doctor_backend/app.py 50
NoneType: None
2024-08-08 20:40:00,002 INFO DataBase set up successfully: /home/frank/virtual_doctor_backend/app.py 62
2024-08-08 20:40:00,127 INFO Migrations set up successfully: /home/frank/virtual_doctor_backend/app.py 74
2024-08-08 20:40:00,169 INFO Blueprints registered successfully: /home/frank/virtual_doctor_backend/app.py 82
2024-08-08 20:40:00,170 INFO Mail service setup successfully: /home/frank/virtual_doctor_backend/app.py 95
2024-08-08 20:40:00,171 INFO App created successfully: /home/frank/virtual_doctor_backend/app.py 105
2024-08-08 20:41:38,630 INFO Logging setup successfully: /home/frank/virtual_doctor_backend/./app.py 32
2024-08-08 20:41:38,631 INFO Uploads directory set up successfully: /home/frank/virtual_doctor_backend/./app.py 50
NoneType: None
2024-08-08 20:41:38,632 INFO DataBase set up successfully: /home/frank/virtual_doctor_backend/./app.py 62
2024-08-08 20:41:38,768 INFO Migrations set up successfully: /home/frank/virtual_doctor_backend/./app.py 74
2024-08-08 20:41:38,840 INFO Blueprints registered successfully: /home/frank/virtual_doctor_backend/./app.py 82
2024-08-08 20:41:38,841 INFO Mail service setup successfully: /home/frank/virtual_doctor_backend/./app.py 95
2024-08-08 20:41:38,841 INFO App created successfully: /home/frank/virtual_doctor_backend/./app.py 105
2024-08-08 20:48:27,383 INFO Logging setup successfully: /home/frank/virtual_doctor_backend/app.py 32
2024-08-08 20:48:27,383 INFO Uploads directory set up successfully: /home/frank/virtual_doctor_backend/app.py 50
NoneType: None
2024-08-08 20:48:27,384 INFO DataBase set up successfully: /home/frank/virtual_doctor_backend/app.py 62
2024-08-08 20:48:27,465 INFO Migrations set up successfully: /home/frank/virtual_doctor_backend/app.py 74
2024-08-08 20:48:27,512 INFO Blueprints registered successfully: /home/frank/virtual_doctor_backend/app.py 82
2024-08-08 20:48:27,513 INFO Mail service setup successfully: /home/frank/virtual_doctor_backend/app.py 95
2024-08-08 20:48:27,513 INFO App created successfully: /home/frank/virtual_doctor_backend/app.py 105
2024-08-08 22:55:07,417 ERROR An error occored while checking the password: /home/frank/virtual_doctor_backend/models/base_model.py 20
Traceback (most recent call last):
  File "/home/frank/virtual_doctor_backend/models/base_model.py", line 18, in check_pwd
    res = bcrypt.checkpw(password.encode('UTF-8'), hashed_pwd)
  File "/usr/lib/python3/dist-packages/bcrypt/__init__.py", line 120, in checkpw
    raise TypeError("Unicode-objects must be encoded before checking")
TypeError: Unicode-objects must be encoded before checking
2024-08-08 22:55:32,238 ERROR An error occored while checking the password: /home/frank/virtual_doctor_backend/models/base_model.py 20
Traceback (most recent call last):
  File "/home/frank/virtual_doctor_backend/models/base_model.py", line 18, in check_pwd
    res = bcrypt.checkpw(password.encode('UTF-8'), hashed_pwd)
  File "/usr/lib/python3/dist-packages/bcrypt/__init__.py", line 120, in checkpw
    raise TypeError("Unicode-objects must be encoded before checking")
TypeError: Unicode-objects must be encoded before checking
2024-08-08 23:25:34,098 INFO Logging setup successfully: /home/frank/virtual_doctor_backend/./app.py 32
2024-08-08 23:25:34,099 INFO Uploads directory set up successfully: /home/frank/virtual_doctor_backend/./app.py 50
NoneType: None
2024-08-08 23:25:34,099 INFO DataBase set up successfully: /home/frank/virtual_doctor_backend/./app.py 62
2024-08-08 23:25:34,234 INFO Migrations set up successfully: /home/frank/virtual_doctor_backend/./app.py 74
2024-08-08 23:25:34,278 INFO Blueprints registered successfully: /home/frank/virtual_doctor_backend/./app.py 82
2024-08-08 23:25:34,279 INFO Mail service setup successfully: /home/frank/virtual_doctor_backend/./app.py 95
2024-08-08 23:25:34,279 INFO App created successfully: /home/frank/virtual_doctor_backend/./app.py 105
2024-08-08 23:33:06,974 INFO Logging setup successfully: /home/frank/virtual_doctor_backend/./app.py 32
2024-08-08 23:33:06,975 INFO Uploads directory set up successfully: /home/frank/virtual_doctor_backend/./app.py 50
NoneType: None
2024-08-08 23:33:06,976 INFO DataBase set up successfully: /home/frank/virtual_doctor_backend/./app.py 62
2024-08-08 23:33:07,099 INFO Migrations set up successfully: /home/frank/virtual_doctor_backend/./app.py 74
2024-08-08 23:33:07,136 INFO Blueprints registered successfully: /home/frank/virtual_doctor_backend/./app.py 82
2024-08-08 23:33:07,136 INFO Mail service setup successfully: /home/frank/virtual_doctor_backend/./app.py 95
2024-08-08 23:33:07,136 INFO App created successfully: /home/frank/virtual_doctor_backend/./app.py 105
2024-08-08 23:34:00,174 INFO Logging setup successfully: /home/frank/virtual_doctor_backend/./app.py 32
2024-08-08 23:34:00,175 INFO Uploads directory set up successfully: /home/frank/virtual_doctor_backend/./app.py 50
NoneType: None
2024-08-08 23:34:00,175 INFO DataBase set up successfully: /home/frank/virtual_doctor_backend/./app.py 62
2024-08-08 23:34:00,298 INFO Migrations set up successfully: /home/frank/virtual_doctor_backend/./app.py 74
2024-08-08 23:34:00,332 INFO Blueprints registered successfully: /home/frank/virtual_doctor_backend/./app.py 82
2024-08-08 23:34:00,332 INFO Mail service setup successfully: /home/frank/virtual_doctor_backend/./app.py 95
2024-08-08 23:34:00,333 INFO App created successfully: /home/frank/virtual_doctor_backend/./app.py 105
2024-08-08 23:37:06,840 INFO Logging setup successfully: /home/frank/virtual_doctor_backend/./app.py 32
2024-08-08 23:37:06,841 INFO Uploads directory set up successfully: /home/frank/virtual_doctor_backend/./app.py 50
NoneType: None
2024-08-08 23:37:06,842 INFO DataBase set up successfully: /home/frank/virtual_doctor_backend/./app.py 62
2024-08-08 23:37:07,077 INFO Migrations set up successfully: /home/frank/virtual_doctor_backend/./app.py 74
2024-08-08 23:37:07,152 INFO Blueprints registered successfully: /home/frank/virtual_doctor_backend/./app.py 82
2024-08-08 23:37:07,152 INFO Mail service setup successfully: /home/frank/virtual_doctor_backend/./app.py 95
2024-08-08 23:37:07,153 INFO App created successfully: /home/frank/virtual_doctor_backend/./app.py 105
2024-08-09 00:21:02,048 INFO Logging setup successfully: /home/frank/virtual_doctor_backend/./app.py 32
2024-08-09 00:21:02,048 INFO Uploads directory set up successfully: /home/frank/virtual_doctor_backend/./app.py 50
NoneType: None
2024-08-09 00:21:02,049 INFO DataBase set up successfully: /home/frank/virtual_doctor_backend/./app.py 62
2024-08-09 00:21:02,180 INFO Migrations set up successfully: /home/frank/virtual_doctor_backend/./app.py 74
2024-08-09 00:21:02,213 INFO Blueprints registered successfully: /home/frank/virtual_doctor_backend/./app.py 82
2024-08-09 00:21:02,213 INFO Mail service setup successfully: /home/frank/virtual_doctor_backend/./app.py 95
2024-08-09 00:21:02,214 INFO App created successfully: /home/frank/virtual_doctor_backend/./app.py 105
2024-08-09 00:21:44,526 ERROR validation error: /home/frank/virtual_doctor_backend/api/auth.py 42
Traceback (most recent call last):
  File "/home/frank/virtual_doctor_backend/api/auth.py", line 40, in register
    schema.load(payload)
  File "/home/frank/.local/lib/python3.10/site-packages/marshmallow/schema.py", line 722, in load
    return self._do_load(
  File "/home/frank/.local/lib/python3.10/site-packages/marshmallow/schema.py", line 909, in _do_load
    raise exc
marshmallow.exceptions.ValidationError: {'_schema': ['Invalid input type.']}
2024-08-09 00:23:28,616 INFO Logging setup successfully: /home/frank/virtual_doctor_backend/./app.py 32
2024-08-09 00:23:28,617 INFO Uploads directory set up successfully: /home/frank/virtual_doctor_backend/./app.py 50
NoneType: None
2024-08-09 00:23:28,617 INFO DataBase set up successfully: /home/frank/virtual_doctor_backend/./app.py 62
2024-08-09 00:23:28,736 INFO Migrations set up successfully: /home/frank/virtual_doctor_backend/./app.py 74
